Workbook

Sheet Atendimento
B1: MEUS VOOS · ATENDIMENTO GUIADO POR E-MAIL · PROGRAMA HORIZONTE
B2: Operador | C2: Brenda Nunes (Manhã) | D2: =Blocos!C5&"," | E2: =TEXT(Blocos!C4,"hh:mm") | F2: C&C = Copiar e Colar | G2: =TEXT(Blocos!C4,"dd/mm/yyyy") | H2: =Blocos!C6 | I2: Dúvidas: aba Terminal
B3: Agora | C3: =Blocos!C4
B4: Assinatura | C4: =IFERROR(INDEX(Equipe!$E$3:$E$14,MATCH($C$2,Equipe!$F$3:$F$14,0)),"Equipe Horizonte")
B5: Supervisor | C5: =IFERROR(INDEX(Equipe!$B$3:$B$14,MATCH($C$2,Equipe!$F$3:$F$14,0)),"")
D6: Atendimento 1 | E6: Atendimento 2 | F6: Atendimento 3 | G6: Atendimento 4 | H6: Atendimento 5 | I6: Atendimento 6
B7: Problema (seletor) | D7: Assento - Remarcação de assento comprado | E7: Cancelamento excepcional - Volta (ida já utilizada) | F7: Emissão - Pontos debitados sem bilhete
B8: C&C Tabulação | D8: =IF(D7="","",INDEX(Problemas!$D$3:$D$28,MATCH(D$7,Problemas!$C$3:$C$28,0))) | E8: =IF(E7="","",INDEX(Problemas!$D$3:$D$28,MATCH(E$7,Problemas!$C$3:$C$28,0))) | F8: =IF(F7="","",INDEX(Problemas!$D$3:$D$28,MATCH(F$7,Problemas!$C$3:$C$28,0))) | G8: =IF(G7="","",INDEX(Problemas!$D$3:$D$28,MATCH(G$7,Problemas!$C$3:$C$28,0))) | H8: =IF(H7="","",INDEX(Problemas!$D$3:$D$28,MATCH(H$7,Problemas!$C$3:$C$28,0))) | I8: =IF(I7="","",INDEX(Problemas!$D$3:$D$28,MATCH(I$7,Problemas!$C$3:$C$28,0)))
B9: C&C Mensagem ao cliente | D9: =IF(D7="","",Blocos!$C$5&", "&IF(D12="","[NOME]",D12)&"! "&Blocos!$C$20&CHAR(10)&CHAR(10)&SUBSTITUTE(SUBSTITUTE(SUBSTITUTE(SUBSTITUTE(INDEX(Problemas!$E$3:$E$28,MATCH(D$7,Problemas!$C$3:$C$28,0)),"{nome}",IF(D12="","[NOME]",D12)),"{loc}",IF(D13="","[LOCALIZADOR]",UPPER(D13))),"{ticket}",IF(D14="","[TICKET]",D14)),"{categoria}",IF(D15="","[CATEGORIA]",D15))&IF(IF(AND(INDEX(Problemas!$H$3:$H$28,MATCH(D$7,Problemas!$C$3:$C$28,0))="Sim",D16<>""),IFERROR(INDEX(Blocos!$C$32:$C$33,MATCH(D16,Blocos!$B$32:$B$33,0)),""),"")="","",CHAR(10)&CHAR(10)&IF(AND(INDEX(Problemas!$H$3:$H$28,MATCH(D$7,Problemas!$C$3:$C$28,0))="Sim",D16<>""),IFERROR(INDEX(Blocos!$C$32:$C$33,MATCH(D16,Blocos!$B$32:$B$33,0)),""),""))&IF(IF(D17="","",IFERROR(INDEX(Blocos!$C$24:$C$28,MATCH(D17,Blocos!$B$24:$B$28,0)),""))="","",CHAR(10)&CHAR(10)&IF(D17="","",IFERROR(INDEX(Blocos!$C$24:$C$28,MATCH(D17,Blocos!$B$24:$B$28,0)),"")))&CHAR(10)&CHAR(10)&Blocos!$C$54&CHAR(10)&CHAR(10)&Blocos!$C$7&" "&Blocos!$C$21&CHAR(10)&CHAR(10)&"Atenciosamente,"&CHAR(10)&$C$4) | E9: =IF(E7="","",Blocos!$C$5&", "&IF(E12="","[NOME]",E12)&"! "&Blocos!$C$20&CHAR(10)&CHAR(10)&SUBSTITUTE(SUBSTITUTE(SUBSTITUTE(SUBSTITUTE(INDEX(Problemas!$E$3:$E$28,MATCH(E$7,Problemas!$C$3:$C$28,0)),"{nome}",IF(E12="","[NOME]",E12)),"{loc}",IF(E13="","[LOCALIZADOR]",UPPER(E13))),"{ticket}",IF(E14="","[TICKET]",E14)),"{categoria}",IF(E15="","[CATEGORIA]",E15))&IF(IF(AND(INDEX(Problemas!$H$3:$H$28,MATCH(E$7,Problemas!$C$3:$C$28,0))="Sim",E16<>""),IFERROR(INDEX(Blocos!$C$32:$C$33,MATCH(E16,Blocos!$B$32:$B$33,0)),""),"")="","",CHAR(10)&CHAR(10)&IF(AND(INDEX(Problemas!$H$3:$H$28,MATCH(E$7,Problemas!$C$3:$C$28,0))="Sim",E16<>""),IFERROR(INDEX(Blocos!$C$32:$C$33,MATCH(E16,Blocos!$B$32:$B$33,0)),""),""))&IF(IF(E17="","",IFERROR(INDEX(Blocos!$C$24:$C$28,MATCH(E17,Blocos!$B$24:$B$28,0)),""))="","",CHAR(10)&CHAR(10)&IF(E17="","",IFERROR(INDEX(Blocos!$C$24:$C$28,MATCH(E17,Blocos!$B$24:$B$28,0)),"")))&CHAR(10)&CHAR(10)&Blocos!$C$54&CHAR(10)&CHAR(10)&Blocos!$C$7&" "&Blocos!$C$21&CHAR(10)&CHAR(10)&"Atenciosamente,"&CHAR(10)&$C$4) | F9: =IF(F7="","",Blocos!$C$5&", "&IF(F12="","[NOME]",F12)&"! "&Blocos!$C$20&CHAR(10)&CHAR(10)&SUBSTITUTE(SUBSTITUTE(SUBSTITUTE(SUBSTITUTE(INDEX(Problemas!$E$3:$E$28,MATCH(F$7,Problemas!$C$3:$C$28,0)),"{nome}",IF(F12="","[NOME]",F12)),"{loc}",IF(F13="","[LOCALIZADOR]",UPPER(F13))),"{ticket}",IF(F14="","[TICKET]",F14)),"{categoria}",IF(F15="","[CATEGORIA]",F15))&IF(IF(AND(INDEX(Problemas!$H$3:$H$28,MATCH(F$7,Problemas!$C$3:$C$28,0))="Sim",F16<>""),IFERROR(INDEX(Blocos!$C$32:$C$33,MATCH(F16,Blocos!$B$32:$B$33,0)),""),"")="","",CHAR(10)&CHAR(10)&IF(AND(INDEX(Problemas!$H$3:$H$28,MATCH(F$7,Problemas!$C$3:$C$28,0))="Sim",F16<>""),IFERROR(INDEX(Blocos!$C$32:$C$33,MATCH(F16,Blocos!$B$32:$B$33,0)),""),""))&IF(IF(F17="","",IFERROR(INDEX(Blocos!$C$24:$C$28,MATCH(F17,Blocos!$B$24:$B$28,0)),""))="","",CHAR(10)&CHAR(10)&IF(F17="","",IFERROR(INDEX(Blocos!$C$24:$C$28,MATCH(F17,Blocos!$B$24:$B$28,0)),"")))&CHAR(10)&CHAR(10)&Blocos!$C$54&CHAR(10)&CHAR(10)&Blocos!$C$7&" "&Blocos!$C$21&CHAR(10)&CHAR(10)&"Atenciosamente,"&CHAR(10)&$C$4) | G9: =IF(G7="","",Blocos!$C$5&", "&IF(G12="","[NOME]",G12)&"! "&Blocos!$C$20&CHAR(10)&CHAR(10)&SUBSTITUTE(SUBSTITUTE(SUBSTITUTE(SUBSTITUTE(INDEX(Problemas!$E$3:$E$28,MATCH(G$7,Problemas!$C$3:$C$28,0)),"{nome}",IF(G12="","[NOME]",G12)),"{loc}",IF(G13="","[LOCALIZADOR]",UPPER(G13))),"{ticket}",IF(G14="","[TICKET]",G14)),"{categoria}",IF(G15="","[CATEGORIA]",G15))&IF(IF(AND(INDEX(Problemas!$H$3:$H$28,MATCH(G$7,Problemas!$C$3:$C$28,0))="Sim",G16<>""),IFERROR(INDEX(Blocos!$C$32:$C$33,MATCH(G16,Blocos!$B$32:$B$33,0)),""),"")="","",CHAR(10)&CHAR(10)&IF(AND(INDEX(Problemas!$H$3:$H$28,MATCH(G$7,Problemas!$C$3:$C$28,0))="Sim",G16<>""),IFERROR(INDEX(Blocos!$C$32:$C$33,MATCH(G16,Blocos!$B$32:$B$33,0)),""),""))&IF(IF(G17="","",IFERROR(INDEX(Blocos!$C$24:$C$28,MATCH(G17,Blocos!$B$24:$B$28,0)),""))="","",CHAR(10)&CHAR(10)&IF(G17="","",IFERROR(INDEX(Blocos!$C$24:$C$28,MATCH(G17,Blocos!$B$24:$B$28,0)),"")))&CHAR(10)&CHAR(10)&Blocos!$C$54&CHAR(10)&CHAR(10)&Blocos!$C$7&" "&Blocos!$C$21&CHAR(10)&CHAR(10)&"Atenciosamente,"&CHAR(10)&$C$4) | H9: =IF(H7="","",Blocos!$C$5&", "&IF(H12="","[NOME]",H12)&"! "&Blocos!$C$20&CHAR(10)&CHAR(10)&SUBSTITUTE(SUBSTITUTE(SUBSTITUTE(SUBSTITUTE(INDEX(Problemas!$E$3:$E$28,MATCH(H$7,Problemas!$C$3:$C$28,0)),"{nome}",IF(H12="","[NOME]",H12)),"{loc}",IF(H13="","[LOCALIZADOR]",UPPER(H13))),"{ticket}",IF(H14="","[TICKET]",H14)),"{categoria}",IF(H15="","[CATEGORIA]",H15))&IF(IF(AND(INDEX(Problemas!$H$3:$H$28,MATCH(H$7,Problemas!$C$3:$C$28,0))="Sim",H16<>""),IFERROR(INDEX(Blocos!$C$32:$C$33,MATCH(H16,Blocos!$B$32:$B$33,0)),""),"")="","",CHAR(10)&CHAR(10)&IF(AND(INDEX(Problemas!$H$3:$H$28,MATCH(H$7,Problemas!$C$3:$C$28,0))="Sim",H16<>""),IFERROR(INDEX(Blocos!$C$32:$C$33,MATCH(H16,Blocos!$B$32:$B$33,0)),""),""))&IF(IF(H17="","",IFERROR(INDEX(Blocos!$C$24:$C$28,MATCH(H17,Blocos!$B$24:$B$28,0)),""))="","",CHAR(10)&CHAR(10)&IF(H17="","",IFERROR(INDEX(Blocos!$C$24:$C$28,MATCH(H17,Blocos!$B$24:$B$28,0)),"")))&CHAR(10)&CHAR(10)&Blocos!$C$54&CHAR(10)&CHAR(10)&Blocos!$C$7&" "&Blocos!$C$21&CHAR(10)&CHAR(10)&"Atenciosamente,"&CHAR(10)&$C$4) | I9: =IF(I7="","",Blocos!$C$5&", "&IF(I12="","[NOME]",I12)&"! "&Blocos!$C$20&CHAR(10)&CHAR(10)&SUBSTITUTE(SUBSTITUTE(SUBSTITUTE(SUBSTITUTE(INDEX(Problemas!$E$3:$E$28,MATCH(I$7,Problemas!$C$3:$C$28,0)),"{nome}",IF(I12="","[NOME]",I12)),"{loc}",IF(I13="","[LOCALIZADOR]",UPPER(I13))),"{ticket}",IF(I14="","[TICKET]",I14)),"{categoria}",IF(I15="","[CATEGORIA]",I15))&IF(IF(AND(INDEX(Problemas!$H$3:$H$28,MATCH(I$7,Problemas!$C$3:$C$28,0))="Sim",I16<>""),IFERROR(INDEX(Blocos!$C$32:$C$33,MATCH(I16,Blocos!$B$32:$B$33,0)),""),"")="","",CHAR(10)&CHAR(10)&IF(AND(INDEX(Problemas!$H$3:$H$28,MATCH(I$7,Problemas!$C$3:$C$28,0))="Sim",I16<>""),IFERROR(INDEX(Blocos!$C$32:$C$33,MATCH(I16,Blocos!$B$32:$B$33,0)),""),""))&IF(IF(I17="","",IFERROR(INDEX(Blocos!$C$24:$C$28,MATCH(I17,Blocos!$B$24:$B$28,0)),""))="","",CHAR(10)&CHAR(10)&IF(I17="","",IFERROR(INDEX(Blocos!$C$24:$C$28,MATCH(I17,Blocos!$B$24:$B$28,0)),"")))&CHAR(10)&CHAR(10)&Blocos!$C$54&CHAR(10)&CHAR(10)&Blocos!$C$7&" "&Blocos!$C$21&CHAR(10)&CHAR(10)&"Atenciosamente,"&CHAR(10)&$C$4)
B10: C&C Registro do atendimento | D10: =IF(D7="","",D7&CHAR(10)&CHAR(10)&SUBSTITUTE(SUBSTITUTE(SUBSTITUTE(SUBSTITUTE(INDEX(Problemas!$F$3:$F$28,MATCH(D$7,Problemas!$C$3:$C$28,0)),"{nome}",IF(D12="","[NOME]",D12)),"{loc}",IF(D13="","[LOCALIZADOR]",UPPER(D13))),"{ticket}",IF(D14="","[TICKET]",D14)),"{categoria}",IF(D15="","[CATEGORIA]",D15))&IF(D16="","",CHAR(10)&"Ida realizada: "&D16)&IF(D17="","",CHAR(10)&"Clube: "&D17)&CHAR(10)&"Localizador: "&IF(D13="","[LOCALIZADOR]",UPPER(D13))&CHAR(10)&"Tabulação: "&D8&CHAR(10)&"Atendente: "&$C$2&" · "&TEXT($C$3,"dd/mm hh:mm")) | E10: =IF(E7="","",E7&CHAR(10)&CHAR(10)&SUBSTITUTE(SUBSTITUTE(SUBSTITUTE(SUBSTITUTE(INDEX(Problemas!$F$3:$F$28,MATCH(E$7,Problemas!$C$3:$C$28,0)),"{nome}",IF(E12="","[NOME]",E12)),"{loc}",IF(E13="","[LOCALIZADOR]",UPPER(E13))),"{ticket}",IF(E14="","[TICKET]",E14)),"{categoria}",IF(E15="","[CATEGORIA]",E15))&IF(E16="","",CHAR(10)&"Ida realizada: "&E16)&IF(E17="","",CHAR(10)&"Clube: "&E17)&CHAR(10)&"Localizador: "&IF(E13="","[LOCALIZADOR]",UPPER(E13))&CHAR(10)&"Tabulação: "&E8&CHAR(10)&"Atendente: "&$C$2&" · "&TEXT($C$3,"dd/mm hh:mm")) | F10: =IF(F7="","",F7&CHAR(10)&CHAR(10)&SUBSTITUTE(SUBSTITUTE(SUBSTITUTE(SUBSTITUTE(INDEX(Problemas!$F$3:$F$28,MATCH(F$7,Problemas!$C$3:$C$28,0)),"{nome}",IF(F12="","[NOME]",F12)),"{loc}",IF(F13="","[LOCALIZADOR]",UPPER(F13))),"{ticket}",IF(F14="","[TICKET]",F14)),"{categoria}",IF(F15="","[CATEGORIA]",F15))&IF(F16="","",CHAR(10)&"Ida realizada: "&F16)&IF(F17="","",CHAR(10)&"Clube: "&F17)&CHAR(10)&"Localizador: "&IF(F13="","[LOCALIZADOR]",UPPER(F13))&CHAR(10)&"Tabulação: "&F8&CHAR(10)&"Atendente: "&$C$2&" · "&TEXT($C$3,"dd/mm hh:mm")) | G10: =IF(G7="","",G7&CHAR(10)&CHAR(10)&SUBSTITUTE(SUBSTITUTE(SUBSTITUTE(SUBSTITUTE(INDEX(Problemas!$F$3:$F$28,MATCH(G$7,Problemas!$C$3:$C$28,0)),"{nome}",IF(G12="","[NOME]",G12)),"{loc}",IF(G13="","[LOCALIZADOR]",UPPER(G13))),"{ticket}",IF(G14="","[TICKET]",G14)),"{categoria}",IF(G15="","[CATEGORIA]",G15))&IF(G16="","",CHAR(10)&"Ida realizada: "&G16)&IF(G17="","",CHAR(10)&"Clube: "&G17)&CHAR(10)&"Localizador: "&IF(G13="","[LOCALIZADOR]",UPPER(G13))&CHAR(10)&"Tabulação: "&G8&CHAR(10)&"Atendente: "&$C$2&" · "&TEXT($C$3,"dd/mm hh:mm")) | H10: =IF(H7="","",H7&CHAR(10)&CHAR(10)&SUBSTITUTE(SUBSTITUTE(SUBSTITUTE(SUBSTITUTE(INDEX(Problemas!$F$3:$F$28,MATCH(H$7,Problemas!$C$3:$C$28,0)),"{nome}",IF(H12="","[NOME]",H12)),"{loc}",IF(H13="","[LOCALIZADOR]",UPPER(H13))),"{ticket}",IF(H14="","[TICKET]",H14)),"{categoria}",IF(H15="","[CATEGORIA]",H15))&IF(H16="","",CHAR(10)&"Ida realizada: "&H16)&IF(H17="","",CHAR(10)&"Clube: "&H17)&CHAR(10)&"Localizador: "&IF(H13="","[LOCALIZADOR]",UPPER(H13))&CHAR(10)&"Tabulação: "&H8&CHAR(10)&"Atendente: "&$C$2&" · "&TEXT($C$3,"dd/mm hh:mm")) | I10: =IF(I7="","",I7&CHAR(10)&CHAR(10)&SUBSTITUTE(SUBSTITUTE(SUBSTITUTE(SUBSTITUTE(INDEX(Problemas!$F$3:$F$28,MATCH(I$7,Problemas!$C$3:$C$28,0)),"{nome}",IF(I12="","[NOME]",I12)),"{loc}",IF(I13="","[LOCALIZADOR]",UPPER(I13))),"{ticket}",IF(I14="","[TICKET]",I14)),"{categoria}",IF(I15="","[CATEGORIA]",I15))&IF(I16="","",CHAR(10)&"Ida realizada: "&I16)&IF(I17="","",CHAR(10)&"Clube: "&I17)&CHAR(10)&"Localizador: "&IF(I13="","[LOCALIZADOR]",UPPER(I13))&CHAR(10)&"Tabulação: "&I8&CHAR(10)&"Atendente: "&$C$2&" · "&TEXT($C$3,"dd/mm hh:mm"))
B11: O que acrescentar | D11: =IF(D7="","",INDEX(Problemas!$G$3:$G$28,MATCH(D$7,Problemas!$C$3:$C$28,0))&IF(INDEX(Problemas!$H$3:$H$28,MATCH(D$7,Problemas!$C$3:$C$28,0))="Sim"," + Ida realizada","")) | E11: =IF(E7="","",INDEX(Problemas!$G$3:$G$28,MATCH(E$7,Problemas!$C$3:$C$28,0))&IF(INDEX(Problemas!$H$3:$H$28,MATCH(E$7,Problemas!$C$3:$C$28,0))="Sim"," + Ida realizada","")) | F11: =IF(F7="","",INDEX(Problemas!$G$3:$G$28,MATCH(F$7,Problemas!$C$3:$C$28,0))&IF(INDEX(Problemas!$H$3:$H$28,MATCH(F$7,Problemas!$C$3:$C$28,0))="Sim"," + Ida realizada","")) | G11: =IF(G7="","",INDEX(Problemas!$G$3:$G$28,MATCH(G$7,Problemas!$C$3:$C$28,0))&IF(INDEX(Problemas!$H$3:$H$28,MATCH(G$7,Problemas!$C$3:$C$28,0))="Sim"," + Ida realizada","")) | H11: =IF(H7="","",INDEX(Problemas!$G$3:$G$28,MATCH(H$7,Problemas!$C$3:$C$28,0))&IF(INDEX(Problemas!$H$3:$H$28,MATCH(H$7,Problemas!$C$3:$C$28,0))="Sim"," + Ida realizada","")) | I11: =IF(I7="","",INDEX(Problemas!$G$3:$G$28,MATCH(I$7,Problemas!$C$3:$C$28,0))&IF(INDEX(Problemas!$H$3:$H$28,MATCH(I$7,Problemas!$C$3:$C$28,0))="Sim"," + Ida realizada",""))
B12: Nome do cliente | D12: Jorge | E12: Marina | F12: Carlos
B13: Localizador | D13: SPAJKS | E13: QW7K2P
B14: Ticket | E14: HZ-204577
B15: Categoria | D15: Ouro | E15: Prata
B16: Ida realizada? | E16: Sim
B17: Status do Clube | D17: Elegível | E17: Suspenso
B18: Falta preencher? | D18: =IF(D7="","",IF(OR(AND(ISNUMBER(SEARCH("Nome",D11)),D12=""),AND(ISNUMBER(SEARCH("Localizador",D11)),D13=""),AND(ISNUMBER(SEARCH("Ticket",D11)),D14=""),AND(ISNUMBER(SEARCH("Categoria",D11)),D15=""),AND(ISNUMBER(SEARCH("Ida",D11)),D16="")),"FALTA INFORMAÇÃO","Pronto para copiar")) | E18: =IF(E7="","",IF(OR(AND(ISNUMBER(SEARCH("Nome",E11)),E12=""),AND(ISNUMBER(SEARCH("Localizador",E11)),E13=""),AND(ISNUMBER(SEARCH("Ticket",E11)),E14=""),AND(ISNUMBER(SEARCH("Categoria",E11)),E15=""),AND(ISNUMBER(SEARCH("Ida",E11)),E16="")),"FALTA INFORMAÇÃO","Pronto para copiar")) | F18: =IF(F7="","",IF(OR(AND(ISNUMBER(SEARCH("Nome",F11)),F12=""),AND(ISNUMBER(SEARCH("Localizador",F11)),F13=""),AND(ISNUMBER(SEARCH("Ticket",F11)),F14=""),AND(ISNUMBER(SEARCH("Categoria",F11)),F15=""),AND(ISNUMBER(SEARCH("Ida",F11)),F16="")),"FALTA INFORMAÇÃO","Pronto para copiar")) | G18: =IF(G7="","",IF(OR(AND(ISNUMBER(SEARCH("Nome",G11)),G12=""),AND(ISNUMBER(SEARCH("Localizador",G11)),G13=""),AND(ISNUMBER(SEARCH("Ticket",G11)),G14=""),AND(ISNUMBER(SEARCH("Categoria",G11)),G15=""),AND(ISNUMBER(SEARCH("Ida",G11)),G16="")),"FALTA INFORMAÇÃO","Pronto para copiar")) | H18: =IF(H7="","",IF(OR(AND(ISNUMBER(SEARCH("Nome",H11)),H12=""),AND(ISNUMBER(SEARCH("Localizador",H11)),H13=""),AND(ISNUMBER(SEARCH("Ticket",H11)),H14=""),AND(ISNUMBER(SEARCH("Categoria",H11)),H15=""),AND(ISNUMBER(SEARCH("Ida",H11)),H16="")),"FALTA INFORMAÇÃO","Pronto para copiar")) | I18: =IF(I7="","",IF(OR(AND(ISNUMBER(SEARCH("Nome",I11)),I12=""),AND(ISNUMBER(SEARCH("Localizador",I11)),I13=""),AND(ISNUMBER(SEARCH("Ticket",I11)),I14=""),AND(ISNUMBER(SEARCH("Categoria",I11)),I15=""),AND(ISNUMBER(SEARCH("Ida",I11)),I16="")),"FALTA INFORMAÇÃO","Pronto para copiar"))

Sheet VN
B1: VN · VOOS NACIONAIS · cole a linha do sistema (formato Sabre: 1 HZ 1245 W CZS BSB 23DEC 1240-2005 1 HK01 /E)
B2: Cole a linha crua do sistema, um trecho por linha
B3: Trecho de ida | C3: 1 HZ 1245 W CZS BSB 23DEC 1240-2005 1 HK01 /E
B4: Conexão 1 | C4: 2 HZ 1286 W BSB VCP 23DEC 2100-2245 0 HK01 /E
B5: Conexão 2
B6: Trecho de volta | C6: 3 MR 2210 Y VCP CZS 02JAN 0815-1330 1 HK01 /E
B7: Conexão 1
B8: Conexão 2
B10: Trecho | C10: Voo | D10: De → Para | E10: Data | F10: Saída | G10: Chegada | H10: Status | I10: Texto (C&C)
B11: =IF($C$3="","","Ida") | C11: =IF($C$3="","",TRIM(MID(SUBSTITUTE(TRIM($C$3)," ",REPT(" ",200)),201,200))&" "&TRIM(MID(SUBSTITUTE(TRIM($C$3)," ",REPT(" ",200)),401,200))&IF(TRIM(MID(SUBSTITUTE(TRIM($C$3)," ",REPT(" ",200)),601,200))=""," "," · classe "&TRIM(MID(SUBSTITUTE(TRIM($C$3)," ",REPT(" ",200)),601,200)))) | D11: =IF($C$3="","",IFERROR(INDEX(Aeroportos!$B$3:$B$37,MATCH(TRIM(MID(SUBSTITUTE(TRIM($C$3)," ",REPT(" ",200)),801,200)),Aeroportos!$A$3:$A$37,0)),TRIM(MID(SUBSTITUTE(TRIM($C$3)," ",REPT(" ",200)),801,200)))&" ("&TRIM(MID(SUBSTITUTE(TRIM($C$3)," ",REPT(" ",200)),801,200))&") → "&IFERROR(INDEX(Aeroportos!$B$3:$B$37,MATCH(TRIM(MID(SUBSTITUTE(TRIM($C$3)," ",REPT(" ",200)),1001,200)),Aeroportos!$A$3:$A$37,0)),TRIM(MID(SUBSTITUTE(TRIM($C$3)," ",REPT(" ",200)),1001,200)))&" ("&TRIM(MID(SUBSTITUTE(TRIM($C$3)," ",REPT(" ",200)),1001,200))&")") | E11: =IF($C$3="","",LEFT(TRIM(MID(SUBSTITUTE(TRIM($C$3)," ",REPT(" ",200)),1201,200)),2)&" de "&IFERROR(INDEX(Aeroportos!$H$3:$H$14,MATCH(MID(TRIM(MID(SUBSTITUTE(TRIM($C$3)," ",REPT(" ",200)),1201,200)),3,3),Aeroportos!$G$3:$G$14,0)),MID(TRIM(MID(SUBSTITUTE(TRIM($C$3)," ",REPT(" ",200)),1201,200)),3,3))) | F11: =IF($C$3="","",LEFT(TRIM(MID(SUBSTITUTE(TRIM($C$3)," ",REPT(" ",200)),1401,200)),2)&":"&MID(TRIM(MID(SUBSTITUTE(TRIM($C$3)," ",REPT(" ",200)),1401,200)),3,2)) | G11: =IF($C$3="","",MID(TRIM(MID(SUBSTITUTE(TRIM($C$3)," ",REPT(" ",200)),1401,200)),6,2)&":"&MID(TRIM(MID(SUBSTITUTE(TRIM($C$3)," ",REPT(" ",200)),1401,200)),8,2)) | H11: =IF($C$3="","",TRIM(MID(SUBSTITUTE(TRIM($C$3)," ",REPT(" ",200)),1801,200))) | I11: =IF($C$3="","",B11&": "&IFERROR(INDEX(Aeroportos!$E$3:$E$8,MATCH(TRIM(MID(SUBSTITUTE(TRIM($C$3)," ",REPT(" ",200)),201,200)),Aeroportos!$D$3:$D$8,0)),TRIM(MID(SUBSTITUTE(TRIM($C$3)," ",REPT(" ",200)),201,200)))&" "&TRIM(MID(SUBSTITUTE(TRIM($C$3)," ",REPT(" ",200)),401,200))&" · "&D11&CHAR(10)&E11&" · "&F11&" – "&G11&"")
B12: =IF($C$4="","","Ida · conexão 1") | C12: =IF($C$4="","",TRIM(MID(SUBSTITUTE(TRIM($C$4)," ",REPT(" ",200)),201,200))&" "&TRIM(MID(SUBSTITUTE(TRIM($C$4)," ",REPT(" ",200)),401,200))&IF(TRIM(MID(SUBSTITUTE(TRIM($C$4)," ",REPT(" ",200)),601,200))=""," "," · classe "&TRIM(MID(SUBSTITUTE(TRIM($C$4)," ",REPT(" ",200)),601,200)))) | D12: =IF($C$4="","",IFERROR(INDEX(Aeroportos!$B$3:$B$37,MATCH(TRIM(MID(SUBSTITUTE(TRIM($C$4)," ",REPT(" ",200)),801,200)),Aeroportos!$A$3:$A$37,0)),TRIM(MID(SUBSTITUTE(TRIM($C$4)," ",REPT(" ",200)),801,200)))&" ("&TRIM(MID(SUBSTITUTE(TRIM($C$4)," ",REPT(" ",200)),801,200))&") → "&IFERROR(INDEX(Aeroportos!$B$3:$B$37,MATCH(TRIM(MID(SUBSTITUTE(TRIM($C$4)," ",REPT(" ",200)),1001,200)),Aeroportos!$A$3:$A$37,0)),TRIM(MID(SUBSTITUTE(TRIM($C$4)," ",REPT(" ",200)),1001,200)))&" ("&TRIM(MID(SUBSTITUTE(TRIM($C$4)," ",REPT(" ",200)),1001,200))&")") | E12: =IF($C$4="","",LEFT(TRIM(MID(SUBSTITUTE(TRIM($C$4)," ",REPT(" ",200)),1201,200)),2)&" de "&IFERROR(INDEX(Aeroportos!$H$3:$H$14,MATCH(MID(TRIM(MID(SUBSTITUTE(TRIM($C$4)," ",REPT(" ",200)),1201,200)),3,3),Aeroportos!$G$3:$G$14,0)),MID(TRIM(MID(SUBSTITUTE(TRIM($C$4)," ",REPT(" ",200)),1201,200)),3,3))) | F12: =IF($C$4="","",LEFT(TRIM(MID(SUBSTITUTE(TRIM($C$4)," ",REPT(" ",200)),1401,200)),2)&":"&MID(TRIM(MID(SUBSTITUTE(TRIM($C$4)," ",REPT(" ",200)),1401,200)),3,2)) | G12: =IF($C$4="","",MID(TRIM(MID(SUBSTITUTE(TRIM($C$4)," ",REPT(" ",200)),1401,200)),6,2)&":"&MID(TRIM(MID(SUBSTITUTE(TRIM($C$4)," ",REPT(" ",200)),1401,200)),8,2)) | H12: =IF($C$4="","",TRIM(MID(SUBSTITUTE(TRIM($C$4)," ",REPT(" ",200)),1801,200))) | I12: =IF($C$4="","",B12&": "&IFERROR(INDEX(Aeroportos!$E$3:$E$8,MATCH(TRIM(MID(SUBSTITUTE(TRIM($C$4)," ",REPT(" ",200)),201,200)),Aeroportos!$D$3:$D$8,0)),TRIM(MID(SUBSTITUTE(TRIM($C$4)," ",REPT(" ",200)),201,200)))&" "&TRIM(MID(SUBSTITUTE(TRIM($C$4)," ",REPT(" ",200)),401,200))&" · "&D12&CHAR(10)&E12&" · "&F12&" – "&G12&"")
B13: =IF($C$5="","","Ida · conexão 2") | C13: =IF($C$5="","",TRIM(MID(SUBSTITUTE(TRIM($C$5)," ",REPT(" ",200)),201,200))&" "&TRIM(MID(SUBSTITUTE(TRIM($C$5)," ",REPT(" ",200)),401,200))&IF(TRIM(MID(SUBSTITUTE(TRIM($C$5)," ",REPT(" ",200)),601,200))=""," "," · classe "&TRIM(MID(SUBSTITUTE(TRIM($C$5)," ",REPT(" ",200)),601,200)))) | D13: =IF($C$5="","",IFERROR(INDEX(Aeroportos!$B$3:$B$37,MATCH(TRIM(MID(SUBSTITUTE(TRIM($C$5)," ",REPT(" ",200)),801,200)),Aeroportos!$A$3:$A$37,0)),TRIM(MID(SUBSTITUTE(TRIM($C$5)," ",REPT(" ",200)),801,200)))&" ("&TRIM(MID(SUBSTITUTE(TRIM($C$5)," ",REPT(" ",200)),801,200))&") → "&IFERROR(INDEX(Aeroportos!$B$3:$B$37,MATCH(TRIM(MID(SUBSTITUTE(TRIM($C$5)," ",REPT(" ",200)),1001,200)),Aeroportos!$A$3:$A$37,0)),TRIM(MID(SUBSTITUTE(TRIM($C$5)," ",REPT(" ",200)),1001,200)))&" ("&TRIM(MID(SUBSTITUTE(TRIM($C$5)," ",REPT(" ",200)),1001,200))&")") | E13: =IF($C$5="","",LEFT(TRIM(MID(SUBSTITUTE(TRIM($C$5)," ",REPT(" ",200)),1201,200)),2)&" de "&IFERROR(INDEX(Aeroportos!$H$3:$H$14,MATCH(MID(TRIM(MID(SUBSTITUTE(TRIM($C$5)," ",REPT(" ",200)),1201,200)),3,3),Aeroportos!$G$3:$G$14,0)),MID(TRIM(MID(SUBSTITUTE(TRIM($C$5)," ",REPT(" ",200)),1201,200)),3,3))) | F13: =IF($C$5="","",LEFT(TRIM(MID(SUBSTITUTE(TRIM($C$5)," ",REPT(" ",200)),1401,200)),2)&":"&MID(TRIM(MID(SUBSTITUTE(TRIM($C$5)," ",REPT(" ",200)),1401,200)),3,2)) | G13: =IF($C$5="","",MID(TRIM(MID(SUBSTITUTE(TRIM($C$5)," ",REPT(" ",200)),1401,200)),6,2)&":"&MID(TRIM(MID(SUBSTITUTE(TRIM($C$5)," ",REPT(" ",200)),1401,200)),8,2)) | H13: =IF($C$5="","",TRIM(MID(SUBSTITUTE(TRIM($C$5)," ",REPT(" ",200)),1801,200))) | I13: =IF($C$5="","",B13&": "&IFERROR(INDEX(Aeroportos!$E$3:$E$8,MATCH(TRIM(MID(SUBSTITUTE(TRIM($C$5)," ",REPT(" ",200)),201,200)),Aeroportos!$D$3:$D$8,0)),TRIM(MID(SUBSTITUTE(TRIM($C$5)," ",REPT(" ",200)),201,200)))&" "&TRIM(MID(SUBSTITUTE(TRIM($C$5)," ",REPT(" ",200)),401,200))&" · "&D13&CHAR(10)&E13&" · "&F13&" – "&G13&"")
B14: =IF($C$6="","","Volta") | C14: =IF($C$6="","",TRIM(MID(SUBSTITUTE(TRIM($C$6)," ",REPT(" ",200)),201,200))&" "&TRIM(MID(SUBSTITUTE(TRIM($C$6)," ",REPT(" ",200)),401,200))&IF(TRIM(MID(SUBSTITUTE(TRIM($C$6)," ",REPT(" ",200)),601,200))=""," "," · classe "&TRIM(MID(SUBSTITUTE(TRIM($C$6)," ",REPT(" ",200)),601,200)))) | D14: =IF($C$6="","",IFERROR(INDEX(Aeroportos!$B$3:$B$37,MATCH(TRIM(MID(SUBSTITUTE(TRIM($C$6)," ",REPT(" ",200)),801,200)),Aeroportos!$A$3:$A$37,0)),TRIM(MID(SUBSTITUTE(TRIM($C$6)," ",REPT(" ",200)),801,200)))&" ("&TRIM(MID(SUBSTITUTE(TRIM($C$6)," ",REPT(" ",200)),801,200))&") → "&IFERROR(INDEX(Aeroportos!$B$3:$B$37,MATCH(TRIM(MID(SUBSTITUTE(TRIM($C$6)," ",REPT(" ",200)),1001,200)),Aeroportos!$A$3:$A$37,0)),TRIM(MID(SUBSTITUTE(TRIM($C$6)," ",REPT(" ",200)),1001,200)))&" ("&TRIM(MID(SUBSTITUTE(TRIM($C$6)," ",REPT(" ",200)),1001,200))&")") | E14: =IF($C$6="","",LEFT(TRIM(MID(SUBSTITUTE(TRIM($C$6)," ",REPT(" ",200)),1201,200)),2)&" de "&IFERROR(INDEX(Aeroportos!$H$3:$H$14,MATCH(MID(TRIM(MID(SUBSTITUTE(TRIM($C$6)," ",REPT(" ",200)),1201,200)),3,3),Aeroportos!$G$3:$G$14,0)),MID(TRIM(MID(SUBSTITUTE(TRIM($C$6)," ",REPT(" ",200)),1201,200)),3,3))) | F14: =IF($C$6="","",LEFT(TRIM(MID(SUBSTITUTE(TRIM($C$6)," ",REPT(" ",200)),1401,200)),2)&":"&MID(TRIM(MID(SUBSTITUTE(TRIM($C$6)," ",REPT(" ",200)),1401,200)),3,2)) | G14: =IF($C$6="","",MID(TRIM(MID(SUBSTITUTE(TRIM($C$6)," ",REPT(" ",200)),1401,200)),6,2)&":"&MID(TRIM(MID(SUBSTITUTE(TRIM($C$6)," ",REPT(" ",200)),1401,200)),8,2)) | H14: =IF($C$6="","",TRIM(MID(SUBSTITUTE(TRIM($C$6)," ",REPT(" ",200)),1801,200))) | I14: =IF($C$6="","",B14&": "&IFERROR(INDEX(Aeroportos!$E$3:$E$8,MATCH(TRIM(MID(SUBSTITUTE(TRIM($C$6)," ",REPT(" ",200)),201,200)),Aeroportos!$D$3:$D$8,0)),TRIM(MID(SUBSTITUTE(TRIM($C$6)," ",REPT(" ",200)),201,200)))&" "&TRIM(MID(SUBSTITUTE(TRIM($C$6)," ",REPT(" ",200)),401,200))&" · "&D14&CHAR(10)&E14&" · "&F14&" – "&G14&"")
B15: =IF($C$7="","","Volta · conexão 1") | C15: =IF($C$7="","",TRIM(MID(SUBSTITUTE(TRIM($C$7)," ",REPT(" ",200)),201,200))&" "&TRIM(MID(SUBSTITUTE(TRIM($C$7)," ",REPT(" ",200)),401,200))&IF(TRIM(MID(SUBSTITUTE(TRIM($C$7)," ",REPT(" ",200)),601,200))=""," "," · classe "&TRIM(MID(SUBSTITUTE(TRIM($C$7)," ",REPT(" ",200)),601,200)))) | D15: =IF($C$7="","",IFERROR(INDEX(Aeroportos!$B$3:$B$37,MATCH(TRIM(MID(SUBSTITUTE(TRIM($C$7)," ",REPT(" ",200)),801,200)),Aeroportos!$A$3:$A$37,0)),TRIM(MID(SUBSTITUTE(TRIM($C$7)," ",REPT(" ",200)),801,200)))&" ("&TRIM(MID(SUBSTITUTE(TRIM($C$7)," ",REPT(" ",200)),801,200))&") → "&IFERROR(INDEX(Aeroportos!$B$3:$B$37,MATCH(TRIM(MID(SUBSTITUTE(TRIM($C$7)," ",REPT(" ",200)),1001,200)),Aeroportos!$A$3:$A$37,0)),TRIM(MID(SUBSTITUTE(TRIM($C$7)," ",REPT(" ",200)),1001,200)))&" ("&TRIM(MID(SUBSTITUTE(TRIM($C$7)," ",REPT(" ",200)),1001,200))&")") | E15: =IF($C$7="","",LEFT(TRIM(MID(SUBSTITUTE(TRIM($C$7)," ",REPT(" ",200)),1201,200)),2)&" de "&IFERROR(INDEX(Aeroportos!$H$3:$H$14,MATCH(MID(TRIM(MID(SUBSTITUTE(TRIM($C$7)," ",REPT(" ",200)),1201,200)),3,3),Aeroportos!$G$3:$G$14,0)),MID(TRIM(MID(SUBSTITUTE(TRIM($C$7)," ",REPT(" ",200)),1201,200)),3,3))) | F15: =IF($C$7="","",LEFT(TRIM(MID(SUBSTITUTE(TRIM($C$7)," ",REPT(" ",200)),1401,200)),2)&":"&MID(TRIM(MID(SUBSTITUTE(TRIM($C$7)," ",REPT(" ",200)),1401,200)),3,2)) | G15: =IF($C$7="","",MID(TRIM(MID(SUBSTITUTE(TRIM($C$7)," ",REPT(" ",200)),1401,200)),6,2)&":"&MID(TRIM(MID(SUBSTITUTE(TRIM($C$7)," ",REPT(" ",200)),1401,200)),8,2)) | H15: =IF($C$7="","",TRIM(MID(SUBSTITUTE(TRIM($C$7)," ",REPT(" ",200)),1801,200))) | I15: =IF($C$7="","",B15&": "&IFERROR(INDEX(Aeroportos!$E$3:$E$8,MATCH(TRIM(MID(SUBSTITUTE(TRIM($C$7)," ",REPT(" ",200)),201,200)),Aeroportos!$D$3:$D$8,0)),TRIM(MID(SUBSTITUTE(TRIM($C$7)," ",REPT(" ",200)),201,200)))&" "&TRIM(MID(SUBSTITUTE(TRIM($C$7)," ",REPT(" ",200)),401,200))&" · "&D15&CHAR(10)&E15&" · "&F15&" – "&G15&"")
B16: =IF($C$8="","","Volta · conexão 2") | C16: =IF($C$8="","",TRIM(MID(SUBSTITUTE(TRIM($C$8)," ",REPT(" ",200)),201,200))&" "&TRIM(MID(SUBSTITUTE(TRIM($C$8)," ",REPT(" ",200)),401,200))&IF(TRIM(MID(SUBSTITUTE(TRIM($C$8)," ",REPT(" ",200)),601,200))=""," "," · classe "&TRIM(MID(SUBSTITUTE(TRIM($C$8)," ",REPT(" ",200)),601,200)))) | D16: =IF($C$8="","",IFERROR(INDEX(Aeroportos!$B$3:$B$37,MATCH(TRIM(MID(SUBSTITUTE(TRIM($C$8)," ",REPT(" ",200)),801,200)),Aeroportos!$A$3:$A$37,0)),TRIM(MID(SUBSTITUTE(TRIM($C$8)," ",REPT(" ",200)),801,200)))&" ("&TRIM(MID(SUBSTITUTE(TRIM($C$8)," ",REPT(" ",200)),801,200))&") → "&IFERROR(INDEX(Aeroportos!$B$3:$B$37,MATCH(TRIM(MID(SUBSTITUTE(TRIM($C$8)," ",REPT(" ",200)),1001,200)),Aeroportos!$A$3:$A$37,0)),TRIM(MID(SUBSTITUTE(TRIM($C$8)," ",REPT(" ",200)),1001,200)))&" ("&TRIM(MID(SUBSTITUTE(TRIM($C$8)," ",REPT(" ",200)),1001,200))&")") | E16: =IF($C$8="","",LEFT(TRIM(MID(SUBSTITUTE(TRIM($C$8)," ",REPT(" ",200)),1201,200)),2)&" de "&IFERROR(INDEX(Aeroportos!$H$3:$H$14,MATCH(MID(TRIM(MID(SUBSTITUTE(TRIM($C$8)," ",REPT(" ",200)),1201,200)),3,3),Aeroportos!$G$3:$G$14,0)),MID(TRIM(MID(SUBSTITUTE(TRIM($C$8)," ",REPT(" ",200)),1201,200)),3,3))) | F16: =IF($C$8="","",LEFT(TRIM(MID(SUBSTITUTE(TRIM($C$8)," ",REPT(" ",200)),1401,200)),2)&":"&MID(TRIM(MID(SUBSTITUTE(TRIM($C$8)," ",REPT(" ",200)),1401,200)),3,2)) | G16: =IF($C$8="","",MID(TRIM(MID(SUBSTITUTE(TRIM($C$8)," ",REPT(" ",200)),1401,200)),6,2)&":"&MID(TRIM(MID(SUBSTITUTE(TRIM($C$8)," ",REPT(" ",200)),1401,200)),8,2)) | H16: =IF($C$8="","",TRIM(MID(SUBSTITUTE(TRIM($C$8)," ",REPT(" ",200)),1801,200))) | I16: =IF($C$8="","",B16&": "&IFERROR(INDEX(Aeroportos!$E$3:$E$8,MATCH(TRIM(MID(SUBSTITUTE(TRIM($C$8)," ",REPT(" ",200)),201,200)),Aeroportos!$D$3:$D$8,0)),TRIM(MID(SUBSTITUTE(TRIM($C$8)," ",REPT(" ",200)),201,200)))&" "&TRIM(MID(SUBSTITUTE(TRIM($C$8)," ",REPT(" ",200)),401,200))&" · "&D16&CHAR(10)&E16&" · "&F16&" – "&G16&"")
B18: COPIAR E COLAR | C18: ="Seu itinerário:"&CHAR(10)&CHAR(10)&IF(I11="","",I11&CHAR(10)&CHAR(10))&IF(I12="","",I12&CHAR(10)&CHAR(10))&IF(I13="","",I13&CHAR(10)&CHAR(10))&IF(I14="","",I14&CHAR(10)&CHAR(10))&IF(I15="","",I15&CHAR(10)&CHAR(10))&IF(I16="","",I16&CHAR(10)&CHAR(10))

Sheet VI
B1: VI · VOOS INTERNACIONAIS · cole a linha do sistema (formato Amadeus: 2 NB1183 T 30APR 3 PRGCDG HK1 1415 1605 30APR E NB/2RO854)
B2: Cole a linha crua do sistema, um trecho por linha
B3: Trecho de ida | C3: 1 KL0792 T 29APR 2 GRUAMS HK1 1830 1035 30APR E KL/2RO854
B4: Conexão 1 | C4: 2 NB1183 T 30APR 3 AMSPRG HK1 1415 1605 30APR E NB/2RO854
B5: Conexão 2
B6: Trecho de volta | C6: 3 NB1184 T 12MAY 1 PRGAMS HK1 0900 1050 12MAY E NB/2RO854
B7: Conexão 1 | C7: 4 KL0791 T 12MAY 1 AMSGRU HK1 1300 2015 12MAY E KL/2RO854
B8: Conexão 2
B10: Trecho | C10: Voo | D10: De → Para | E10: Data | F10: Saída | G10: Chegada | H10: Status | I10: Texto (C&C)
B11: =IF($C$3="","","Ida") | C11: =IF($C$3="","",LEFT(TRIM(MID(SUBSTITUTE(TRIM($C$3)," ",REPT(" ",200)),201,200)),2)&" "&MID(TRIM(MID(SUBSTITUTE(TRIM($C$3)," ",REPT(" ",200)),201,200)),3,10)&IF(TRIM(MID(SUBSTITUTE(TRIM($C$3)," ",REPT(" ",200)),401,200))=""," "," · classe "&TRIM(MID(SUBSTITUTE(TRIM($C$3)," ",REPT(" ",200)),401,200)))) | D11: =IF($C$3="","",IFERROR(INDEX(Aeroportos!$B$3:$B$37,MATCH(LEFT(TRIM(MID(SUBSTITUTE(TRIM($C$3)," ",REPT(" ",200)),1001,200)),3),Aeroportos!$A$3:$A$37,0)),LEFT(TRIM(MID(SUBSTITUTE(TRIM($C$3)," ",REPT(" ",200)),1001,200)),3))&" ("&LEFT(TRIM(MID(SUBSTITUTE(TRIM($C$3)," ",REPT(" ",200)),1001,200)),3)&") → "&IFERROR(INDEX(Aeroportos!$B$3:$B$37,MATCH(MID(TRIM(MID(SUBSTITUTE(TRIM($C$3)," ",REPT(" ",200)),1001,200)),4,3),Aeroportos!$A$3:$A$37,0)),MID(TRIM(MID(SUBSTITUTE(TRIM($C$3)," ",REPT(" ",200)),1001,200)),4,3))&" ("&MID(TRIM(MID(SUBSTITUTE(TRIM($C$3)," ",REPT(" ",200)),1001,200)),4,3)&")") | E11: =IF($C$3="","",LEFT(TRIM(MID(SUBSTITUTE(TRIM($C$3)," ",REPT(" ",200)),601,200)),2)&" de "&IFERROR(INDEX(Aeroportos!$H$3:$H$14,MATCH(MID(TRIM(MID(SUBSTITUTE(TRIM($C$3)," ",REPT(" ",200)),601,200)),3,3),Aeroportos!$G$3:$G$14,0)),MID(TRIM(MID(SUBSTITUTE(TRIM($C$3)," ",REPT(" ",200)),601,200)),3,3))) | F11: =IF($C$3="","",LEFT(TRIM(MID(SUBSTITUTE(TRIM($C$3)," ",REPT(" ",200)),1401,200)),2)&":"&MID(TRIM(MID(SUBSTITUTE(TRIM($C$3)," ",REPT(" ",200)),1401,200)),3,2)) | G11: =IF($C$3="","",LEFT(TRIM(MID(SUBSTITUTE(TRIM($C$3)," ",REPT(" ",200)),1601,200)),2)&":"&MID(TRIM(MID(SUBSTITUTE(TRIM($C$3)," ",REPT(" ",200)),1601,200)),3,2)&IF(TRIM(MID(SUBSTITUTE(TRIM($C$3)," ",REPT(" ",200)),1801,200))<>TRIM(MID(SUBSTITUTE(TRIM($C$3)," ",REPT(" ",200)),601,200))," (dia seguinte)","")) | H11: =IF($C$3="","",TRIM(MID(SUBSTITUTE(TRIM($C$3)," ",REPT(" ",200)),1201,200))) | I11: =IF($C$3="","",B11&": "&IFERROR(INDEX(Aeroportos!$E$3:$E$8,MATCH(LEFT(TRIM(MID(SUBSTITUTE(TRIM($C$3)," ",REPT(" ",200)),201,200)),2),Aeroportos!$D$3:$D$8,0)),LEFT(TRIM(MID(SUBSTITUTE(TRIM($C$3)," ",REPT(" ",200)),201,200)),2))&" "&MID(TRIM(MID(SUBSTITUTE(TRIM($C$3)," ",REPT(" ",200)),201,200)),3,10)&" · "&D11&CHAR(10)&E11&" · "&F11&" – "&G11&" · localizador "&MID(TRIM(MID(SUBSTITUTE(TRIM($C$3)," ",REPT(" ",200)),2201,200)),4,10))
B12: =IF($C$4="","","Ida · conexão 1") | C12: =IF($C$4="","",LEFT(TRIM(MID(SUBSTITUTE(TRIM($C$4)," ",REPT(" ",200)),201,200)),2)&" "&MID(TRIM(MID(SUBSTITUTE(TRIM($C$4)," ",REPT(" ",200)),201,200)),3,10)&IF(TRIM(MID(SUBSTITUTE(TRIM($C$4)," ",REPT(" ",200)),401,200))=""," "," · classe "&TRIM(MID(SUBSTITUTE(TRIM($C$4)," ",REPT(" ",200)),401,200)))) | D12: =IF($C$4="","",IFERROR(INDEX(Aeroportos!$B$3:$B$37,MATCH(LEFT(TRIM(MID(SUBSTITUTE(TRIM($C$4)," ",REPT(" ",200)),1001,200)),3),Aeroportos!$A$3:$A$37,0)),LEFT(TRIM(MID(SUBSTITUTE(TRIM($C$4)," ",REPT(" ",200)),1001,200)),3))&" ("&LEFT(TRIM(MID(SUBSTITUTE(TRIM($C$4)," ",REPT(" ",200)),1001,200)),3)&") → "&IFERROR(INDEX(Aeroportos!$B$3:$B$37,MATCH(MID(TRIM(MID(SUBSTITUTE(TRIM($C$4)," ",REPT(" ",200)),1001,200)),4,3),Aeroportos!$A$3:$A$37,0)),MID(TRIM(MID(SUBSTITUTE(TRIM($C$4)," ",REPT(" ",200)),1001,200)),4,3))&" ("&MID(TRIM(MID(SUBSTITUTE(TRIM($C$4)," ",REPT(" ",200)),1001,200)),4,3)&")") | E12: =IF($C$4="","",LEFT(TRIM(MID(SUBSTITUTE(TRIM($C$4)," ",REPT(" ",200)),601,200)),2)&" de "&IFERROR(INDEX(Aeroportos!$H$3:$H$14,MATCH(MID(TRIM(MID(SUBSTITUTE(TRIM($C$4)," ",REPT(" ",200)),601,200)),3,3),Aeroportos!$G$3:$G$14,0)),MID(TRIM(MID(SUBSTITUTE(TRIM($C$4)," ",REPT(" ",200)),601,200)),3,3))) | F12: =IF($C$4="","",LEFT(TRIM(MID(SUBSTITUTE(TRIM($C$4)," ",REPT(" ",200)),1401,200)),2)&":"&MID(TRIM(MID(SUBSTITUTE(TRIM($C$4)," ",REPT(" ",200)),1401,200)),3,2)) | G12: =IF($C$4="","",LEFT(TRIM(MID(SUBSTITUTE(TRIM($C$4)," ",REPT(" ",200)),1601,200)),2)&":"&MID(TRIM(MID(SUBSTITUTE(TRIM($C$4)," ",REPT(" ",200)),1601,200)),3,2)&IF(TRIM(MID(SUBSTITUTE(TRIM($C$4)," ",REPT(" ",200)),1801,200))<>TRIM(MID(SUBSTITUTE(TRIM($C$4)," ",REPT(" ",200)),601,200))," (dia seguinte)","")) | H12: =IF($C$4="","",TRIM(MID(SUBSTITUTE(TRIM($C$4)," ",REPT(" ",200)),1201,200))) | I12: =IF($C$4="","",B12&": "&IFERROR(INDEX(Aeroportos!$E$3:$E$8,MATCH(LEFT(TRIM(MID(SUBSTITUTE(TRIM($C$4)," ",REPT(" ",200)),201,200)),2),Aeroportos!$D$3:$D$8,0)),LEFT(TRIM(MID(SUBSTITUTE(TRIM($C$4)," ",REPT(" ",200)),201,200)),2))&" "&MID(TRIM(MID(SUBSTITUTE(TRIM($C$4)," ",REPT(" ",200)),201,200)),3,10)&" · "&D12&CHAR(10)&E12&" · "&F12&" – "&G12&" · localizador "&MID(TRIM(MID(SUBSTITUTE(TRIM($C$4)," ",REPT(" ",200)),2201,200)),4,10))
B13: =IF($C$5="","","Ida · conexão 2") | C13: =IF($C$5="","",LEFT(TRIM(MID(SUBSTITUTE(TRIM($C$5)," ",REPT(" ",200)),201,200)),2)&" "&MID(TRIM(MID(SUBSTITUTE(TRIM($C$5)," ",REPT(" ",200)),201,200)),3,10)&IF(TRIM(MID(SUBSTITUTE(TRIM($C$5)," ",REPT(" ",200)),401,200))=""," "," · classe "&TRIM(MID(SUBSTITUTE(TRIM($C$5)," ",REPT(" ",200)),401,200)))) | D13: =IF($C$5="","",IFERROR(INDEX(Aeroportos!$B$3:$B$37,MATCH(LEFT(TRIM(MID(SUBSTITUTE(TRIM($C$5)," ",REPT(" ",200)),1001,200)),3),Aeroportos!$A$3:$A$37,0)),LEFT(TRIM(MID(SUBSTITUTE(TRIM($C$5)," ",REPT(" ",200)),1001,200)),3))&" ("&LEFT(TRIM(MID(SUBSTITUTE(TRIM($C$5)," ",REPT(" ",200)),1001,200)),3)&") → "&IFERROR(INDEX(Aeroportos!$B$3:$B$37,MATCH(MID(TRIM(MID(SUBSTITUTE(TRIM($C$5)," ",REPT(" ",200)),1001,200)),4,3),Aeroportos!$A$3:$A$37,0)),MID(TRIM(MID(SUBSTITUTE(TRIM($C$5)," ",REPT(" ",200)),1001,200)),4,3))&" ("&MID(TRIM(MID(SUBSTITUTE(TRIM($C$5)," ",REPT(" ",200)),1001,200)),4,3)&")") | E13: =IF($C$5="","",LEFT(TRIM(MID(SUBSTITUTE(TRIM($C$5)," ",REPT(" ",200)),601,200)),2)&" de "&IFERROR(INDEX(Aeroportos!$H$3:$H$14,MATCH(MID(TRIM(MID(SUBSTITUTE(TRIM($C$5)," ",REPT(" ",200)),601,200)),3,3),Aeroportos!$G$3:$G$14,0)),MID(TRIM(MID(SUBSTITUTE(TRIM($C$5)," ",REPT(" ",200)),601,200)),3,3))) | F13: =IF($C$5="","",LEFT(TRIM(MID(SUBSTITUTE(TRIM($C$5)," ",REPT(" ",200)),1401,200)),2)&":"&MID(TRIM(MID(SUBSTITUTE(TRIM($C$5)," ",REPT(" ",200)),1401,200)),3,2)) | G13: =IF($C$5="","",LEFT(TRIM(MID(SUBSTITUTE(TRIM($C$5)," ",REPT(" ",200)),1601,200)),2)&":"&MID(TRIM(MID(SUBSTITUTE(TRIM($C$5)," ",REPT(" ",200)),1601,200)),3,2)&IF(TRIM(MID(SUBSTITUTE(TRIM($C$5)," ",REPT(" ",200)),1801,200))<>TRIM(MID(SUBSTITUTE(TRIM($C$5)," ",REPT(" ",200)),601,200))," (dia seguinte)","")) | H13: =IF($C$5="","",TRIM(MID(SUBSTITUTE(TRIM($C$5)," ",REPT(" ",200)),1201,200))) | I13: =IF($C$5="","",B13&": "&IFERROR(INDEX(Aeroportos!$E$3:$E$8,MATCH(LEFT(TRIM(MID(SUBSTITUTE(TRIM($C$5)," ",REPT(" ",200)),201,200)),2),Aeroportos!$D$3:$D$8,0)),LEFT(TRIM(MID(SUBSTITUTE(TRIM($C$5)," ",REPT(" ",200)),201,200)),2))&" "&MID(TRIM(MID(SUBSTITUTE(TRIM($C$5)," ",REPT(" ",200)),201,200)),3,10)&" · "&D13&CHAR(10)&E13&" · "&F13&" – "&G13&" · localizador "&MID(TRIM(MID(SUBSTITUTE(TRIM($C$5)," ",REPT(" ",200)),2201,200)),4,10))
B14: =IF($C$6="","","Volta") | C14: =IF($C$6="","",LEFT(TRIM(MID(SUBSTITUTE(TRIM($C$6)," ",REPT(" ",200)),201,200)),2)&" "&MID(TRIM(MID(SUBSTITUTE(TRIM($C$6)," ",REPT(" ",200)),201,200)),3,10)&IF(TRIM(MID(SUBSTITUTE(TRIM($C$6)," ",REPT(" ",200)),401,200))=""," "," · classe "&TRIM(MID(SUBSTITUTE(TRIM($C$6)," ",REPT(" ",200)),401,200)))) | D14: =IF($C$6="","",IFERROR(INDEX(Aeroportos!$B$3:$B$37,MATCH(LEFT(TRIM(MID(SUBSTITUTE(TRIM($C$6)," ",REPT(" ",200)),1001,200)),3),Aeroportos!$A$3:$A$37,0)),LEFT(TRIM(MID(SUBSTITUTE(TRIM($C$6)," ",REPT(" ",200)),1001,200)),3))&" ("&LEFT(TRIM(MID(SUBSTITUTE(TRIM($C$6)," ",REPT(" ",200)),1001,200)),3)&") → "&IFERROR(INDEX(Aeroportos!$B$3:$B$37,MATCH(MID(TRIM(MID(SUBSTITUTE(TRIM($C$6)," ",REPT(" ",200)),1001,200)),4,3),Aeroportos!$A$3:$A$37,0)),MID(TRIM(MID(SUBSTITUTE(TRIM($C$6)," ",REPT(" ",200)),1001,200)),4,3))&" ("&MID(TRIM(MID(SUBSTITUTE(TRIM($C$6)," ",REPT(" ",200)),1001,200)),4,3)&")") | E14: =IF($C$6="","",LEFT(TRIM(MID(SUBSTITUTE(TRIM($C$6)," ",REPT(" ",200)),601,200)),2)&" de "&IFERROR(INDEX(Aeroportos!$H$3:$H$14,MATCH(MID(TRIM(MID(SUBSTITUTE(TRIM($C$6)," ",REPT(" ",200)),601,200)),3,3),Aeroportos!$G$3:$G$14,0)),MID(TRIM(MID(SUBSTITUTE(TRIM($C$6)," ",REPT(" ",200)),601,200)),3,3))) | F14: =IF($C$6="","",LEFT(TRIM(MID(SUBSTITUTE(TRIM($C$6)," ",REPT(" ",200)),1401,200)),2)&":"&MID(TRIM(MID(SUBSTITUTE(TRIM($C$6)," ",REPT(" ",200)),1401,200)),3,2)) | G14: =IF($C$6="","",LEFT(TRIM(MID(SUBSTITUTE(TRIM($C$6)," ",REPT(" ",200)),1601,200)),2)&":"&MID(TRIM(MID(SUBSTITUTE(TRIM($C$6)," ",REPT(" ",200)),1601,200)),3,2)&IF(TRIM(MID(SUBSTITUTE(TRIM($C$6)," ",REPT(" ",200)),1801,200))<>TRIM(MID(SUBSTITUTE(TRIM($C$6)," ",REPT(" ",200)),601,200))," (dia seguinte)","")) | H14: =IF($C$6="","",TRIM(MID(SUBSTITUTE(TRIM($C$6)," ",REPT(" ",200)),1201,200))) | I14: =IF($C$6="","",B14&": "&IFERROR(INDEX(Aeroportos!$E$3:$E$8,MATCH(LEFT(TRIM(MID(SUBSTITUTE(TRIM($C$6)," ",REPT(" ",200)),201,200)),2),Aeroportos!$D$3:$D$8,0)),LEFT(TRIM(MID(SUBSTITUTE(TRIM($C$6)," ",REPT(" ",200)),201,200)),2))&" "&MID(TRIM(MID(SUBSTITUTE(TRIM($C$6)," ",REPT(" ",200)),201,200)),3,10)&" · "&D14&CHAR(10)&E14&" · "&F14&" – "&G14&" · localizador "&MID(TRIM(MID(SUBSTITUTE(TRIM($C$6)," ",REPT(" ",200)),2201,200)),4,10))
B15: =IF($C$7="","","Volta · conexão 1") | C15: =IF($C$7="","",LEFT(TRIM(MID(SUBSTITUTE(TRIM($C$7)," ",REPT(" ",200)),201,200)),2)&" "&MID(TRIM(MID(SUBSTITUTE(TRIM($C$7)," ",REPT(" ",200)),201,200)),3,10)&IF(TRIM(MID(SUBSTITUTE(TRIM($C$7)," ",REPT(" ",200)),401,200))=""," "," · classe "&TRIM(MID(SUBSTITUTE(TRIM($C$7)," ",REPT(" ",200)),401,200)))) | D15: =IF($C$7="","",IFERROR(INDEX(Aeroportos!$B$3:$B$37,MATCH(LEFT(TRIM(MID(SUBSTITUTE(TRIM($C$7)," ",REPT(" ",200)),1001,200)),3),Aeroportos!$A$3:$A$37,0)),LEFT(TRIM(MID(SUBSTITUTE(TRIM($C$7)," ",REPT(" ",200)),1001,200)),3))&" ("&LEFT(TRIM(MID(SUBSTITUTE(TRIM($C$7)," ",REPT(" ",200)),1001,200)),3)&") → "&IFERROR(INDEX(Aeroportos!$B$3:$B$37,MATCH(MID(TRIM(MID(SUBSTITUTE(TRIM($C$7)," ",REPT(" ",200)),1001,200)),4,3),Aeroportos!$A$3:$A$37,0)),MID(TRIM(MID(SUBSTITUTE(TRIM($C$7)," ",REPT(" ",200)),1001,200)),4,3))&" ("&MID(TRIM(MID(SUBSTITUTE(TRIM($C$7)," ",REPT(" ",200)),1001,200)),4,3)&")") | E15: =IF($C$7="","",LEFT(TRIM(MID(SUBSTITUTE(TRIM($C$7)," ",REPT(" ",200)),601,200)),2)&" de "&IFERROR(INDEX(Aeroportos!$H$3:$H$14,MATCH(MID(TRIM(MID(SUBSTITUTE(TRIM($C$7)," ",REPT(" ",200)),601,200)),3,3),Aeroportos!$G$3:$G$14,0)),MID(TRIM(MID(SUBSTITUTE(TRIM($C$7)," ",REPT(" ",200)),601,200)),3,3))) | F15: =IF($C$7="","",LEFT(TRIM(MID(SUBSTITUTE(TRIM($C$7)," ",REPT(" ",200)),1401,200)),2)&":"&MID(TRIM(MID(SUBSTITUTE(TRIM($C$7)," ",REPT(" ",200)),1401,200)),3,2)) | G15: =IF($C$7="","",LEFT(TRIM(MID(SUBSTITUTE(TRIM($C$7)," ",REPT(" ",200)),1601,200)),2)&":"&MID(TRIM(MID(SUBSTITUTE(TRIM($C$7)," ",REPT(" ",200)),1601,200)),3,2)&IF(TRIM(MID(SUBSTITUTE(TRIM($C$7)," ",REPT(" ",200)),1801,200))<>TRIM(MID(SUBSTITUTE(TRIM($C$7)," ",REPT(" ",200)),601,200))," (dia seguinte)","")) | H15: =IF($C$7="","",TRIM(MID(SUBSTITUTE(TRIM($C$7)," ",REPT(" ",200)),1201,200))) | I15: =IF($C$7="","",B15&": "&IFERROR(INDEX(Aeroportos!$E$3:$E$8,MATCH(LEFT(TRIM(MID(SUBSTITUTE(TRIM($C$7)," ",REPT(" ",200)),201,200)),2),Aeroportos!$D$3:$D$8,0)),LEFT(TRIM(MID(SUBSTITUTE(TRIM($C$7)," ",REPT(" ",200)),201,200)),2))&" "&MID(TRIM(MID(SUBSTITUTE(TRIM($C$7)," ",REPT(" ",200)),201,200)),3,10)&" · "&D15&CHAR(10)&E15&" · "&F15&" – "&G15&" · localizador "&MID(TRIM(MID(SUBSTITUTE(TRIM($C$7)," ",REPT(" ",200)),2201,200)),4,10))
B16: =IF($C$8="","","Volta · conexão 2") | C16: =IF($C$8="","",LEFT(TRIM(MID(SUBSTITUTE(TRIM($C$8)," ",REPT(" ",200)),201,200)),2)&" "&MID(TRIM(MID(SUBSTITUTE(TRIM($C$8)," ",REPT(" ",200)),201,200)),3,10)&IF(TRIM(MID(SUBSTITUTE(TRIM($C$8)," ",REPT(" ",200)),401,200))=""," "," · classe "&TRIM(MID(SUBSTITUTE(TRIM($C$8)," ",REPT(" ",200)),401,200)))) | D16: =IF($C$8="","",IFERROR(INDEX(Aeroportos!$B$3:$B$37,MATCH(LEFT(TRIM(MID(SUBSTITUTE(TRIM($C$8)," ",REPT(" ",200)),1001,200)),3),Aeroportos!$A$3:$A$37,0)),LEFT(TRIM(MID(SUBSTITUTE(TRIM($C$8)," ",REPT(" ",200)),1001,200)),3))&" ("&LEFT(TRIM(MID(SUBSTITUTE(TRIM($C$8)," ",REPT(" ",200)),1001,200)),3)&") → "&IFERROR(INDEX(Aeroportos!$B$3:$B$37,MATCH(MID(TRIM(MID(SUBSTITUTE(TRIM($C$8)," ",REPT(" ",200)),1001,200)),4,3),Aeroportos!$A$3:$A$37,0)),MID(TRIM(MID(SUBSTITUTE(TRIM($C$8)," ",REPT(" ",200)),1001,200)),4,3))&" ("&MID(TRIM(MID(SUBSTITUTE(TRIM($C$8)," ",REPT(" ",200)),1001,200)),4,3)&")") | E16: =IF($C$8="","",LEFT(TRIM(MID(SUBSTITUTE(TRIM($C$8)," ",REPT(" ",200)),601,200)),2)&" de "&IFERROR(INDEX(Aeroportos!$H$3:$H$14,MATCH(MID(TRIM(MID(SUBSTITUTE(TRIM($C$8)," ",REPT(" ",200)),601,200)),3,3),Aeroportos!$G$3:$G$14,0)),MID(TRIM(MID(SUBSTITUTE(TRIM($C$8)," ",REPT(" ",200)),601,200)),3,3))) | F16: =IF($C$8="","",LEFT(TRIM(MID(SUBSTITUTE(TRIM($C$8)," ",REPT(" ",200)),1401,200)),2)&":"&MID(TRIM(MID(SUBSTITUTE(TRIM($C$8)," ",REPT(" ",200)),1401,200)),3,2)) | G16: =IF($C$8="","",LEFT(TRIM(MID(SUBSTITUTE(TRIM($C$8)," ",REPT(" ",200)),1601,200)),2)&":"&MID(TRIM(MID(SUBSTITUTE(TRIM($C$8)," ",REPT(" ",200)),1601,200)),3,2)&IF(TRIM(MID(SUBSTITUTE(TRIM($C$8)," ",REPT(" ",200)),1801,200))<>TRIM(MID(SUBSTITUTE(TRIM($C$8)," ",REPT(" ",200)),601,200))," (dia seguinte)","")) | H16: =IF($C$8="","",TRIM(MID(SUBSTITUTE(TRIM($C$8)," ",REPT(" ",200)),1201,200))) | I16: =IF($C$8="","",B16&": "&IFERROR(INDEX(Aeroportos!$E$3:$E$8,MATCH(LEFT(TRIM(MID(SUBSTITUTE(TRIM($C$8)," ",REPT(" ",200)),201,200)),2),Aeroportos!$D$3:$D$8,0)),LEFT(TRIM(MID(SUBSTITUTE(TRIM($C$8)," ",REPT(" ",200)),201,200)),2))&" "&MID(TRIM(MID(SUBSTITUTE(TRIM($C$8)," ",REPT(" ",200)),201,200)),3,10)&" · "&D16&CHAR(10)&E16&" · "&F16&" – "&G16&" · localizador "&MID(TRIM(MID(SUBSTITUTE(TRIM($C$8)," ",REPT(" ",200)),2201,200)),4,10))
B18: COPIAR E COLAR | C18: ="Seu itinerário:"&CHAR(10)&CHAR(10)&IF(I11="","",I11&CHAR(10)&CHAR(10))&IF(I12="","",I12&CHAR(10)&CHAR(10))&IF(I13="","",I13&CHAR(10)&CHAR(10))&IF(I14="","",I14&CHAR(10)&CHAR(10))&IF(I15="","",I15&CHAR(10)&CHAR(10))&IF(I16="","",I16&CHAR(10)&CHAR(10))

Sheet Terminal
B2: > A planilha é simples de se utilizar, aqui vão as regras de como ela funciona
B4: - Em ATENDIMENTO, escolha seu nome no campo Operador.
B5: - Insira o problema do cliente no "Problema (seletor)".
B6: - Coloque as informações que a planilha pede na linha "O que acrescentar".
B7: - Linhas de cor FORTE: precisa acrescentar informação. Linhas CLARAS: só Copiar e Colar (C&C).
B8: - Se um campo estiver em VERMELHO: falta informação. Quando a última linha ficar VERDE: pronto para copiar.
B9: - A mensagem muda sozinha: saudação pelo horário, despedida pelo dia, emoji sorteado,
B10: parágrafo do Clube conforme o status escolhido, e a regra de ida realizada nos cancelamentos.
B12: > VN e VI (itinerário)
B13: - Cole a linha crua do sistema de reservas, um trecho por linha (ida, conexões, volta, conexões).
B14: - VN = voos nacionais (formato Sabre, vermelho). VI = voos internacionais (formato Amadeus, azul).
B15: - A planilha separa companhia, voo, classe, origem, destino, data e horários e monta o texto para C&C.
... B24: - A original tinha 263 problemas, um bloco por operador e dois turnos (manhã e tarde).

Sheet Problemas
A1: BASE DE PROBLEMAS · tabulação, mensagem e registro por problema · placeholders: {nome} {loc} {ticket} {categoria}
A2: # | B2: Categoria | C2: Problema | D2: Tabulação | E2: Mensagem ao cliente | F2: Registro do atendimento | G2: O que acrescentar | H2: Depende da ida?
A3: 1 | B3: Alteração involuntária | C3: Alteração involuntária - Acima de 30 min (ANAC 400) | D3: Solicitação > Aéreas > Alteração involuntária > Reacomodação | E3: Em atenção à sua solicitação sobre o localizador {loc}, confirmo que o voo sofreu alteração acima do que regulamenta a Resolução 400 da ANAC. Nesse caso, você pode escolher entre: reacomodação em outro voo da mesma companhia sem custo, reembolso integral, ou crédito para uso futuro. Me diga qual opção prefere e sigo com a solicitação. | F3: Alteração involuntária acima de 30 min (ANAC 400). Cliente contatou sobre alteração de voo. Orientado sobre as três opções (reacomodação, reembolso, crédito). Aguardando escolha do cliente. | G3: Nome + Localizador | H3: Não
A4: 2 | B4: Alteração involuntária | C4: Alteração involuntária - Cliente aceitou voo proposto | D4: Solicitação > Aéreas > Alteração involuntária > Cliente aceitou voo proposto | E4: Muito obrigado pelo seu retorno sobre o localizador {loc}. Seu voo acabou de ser acomodado de acordo com a sua confirmação de horário. Você receberá um e-mail da companhia com o novo bilhete em até 24 horas. Lembrando: enquanto a acomodação é processada, não abra a reserva no site ou no aplicativo e não realize check-in, pois isso impede a confirmação da alteração. | F4: Alteração involuntária. Cliente aceitou o voo proposto. Acomodação realizada conforme confirmação do cliente. | G4: Nome + Localizador | H4: Não
A5: 3 | B5: Alteração involuntária | C5: Alteração involuntária - Inferior a 30 min (sem direito) | D5: Informação > Aéreas > Alteração involuntária > Regulamento | E5: Em atenção à sua solicitação sobre o localizador {loc}, verifiquei que a alteração feita pela companhia foi inferior a 30 minutos. Pela Resolução 400 da ANAC, alterações dentro desse limite não geram direito a reacomodação gratuita ou reembolso. O voo segue confirmado no novo horário. | F5: Alteração involuntária inferior a 30 min. Cliente informado que a alteração está dentro do limite regulamentar; sem direito a reacomodação ou reembolso. | G5: Nome + Localizador | H5: Não
A6: 4 | B6: Alteração voluntária | C6: Alteração voluntária - Tarifa permite (com custos) | D6: Solicitação > Aéreas > Alteração voluntária > Com custos | E6: Em atenção à sua solicitação sobre o localizador {loc}, a tarifa da sua passagem permite alteração mediante taxa e diferença tarifária, quando houver. Para seguir, me informe a nova data e o horário desejados. Retorno com os valores para sua aprovação antes de qualquer cobrança. | F6: Alteração voluntária, tarifa permite com custos. Cliente orientado sobre taxa e diferença tarifária. Aguardando nova data para cotação. | G6: Nome + Localizador | H6: Não
A7: 5 | B7: Alteração voluntária | C7: Alteração voluntária - Tarifa não permite | D7: Informação > Aéreas > Alteração voluntária > Tarifa não permite | E7: Em atenção à sua solicitação sobre o localizador {loc}, verifiquei que a tarifa adquirida não permite alteração de data ou horário. As alternativas são: manter o voo como está, ou cancelar e emitir uma nova passagem (o cancelamento segue as regras da tarifa). Se quiser, verifico as condições de cancelamento para você. | F7: Alteração voluntária, tarifa não permite. Cliente informado das regras da tarifa e das alternativas. | G7: Nome + Localizador | H7: Não
A8: 6 | B8: Alteração voluntária | C8: Alteração voluntária - Trecho já voado | D8: Informação > Aéreas > Alteração voluntária > Trecho já voado | E8: Em atenção à sua solicitação sobre o localizador {loc}, o trecho de ida já foi utilizado. A alteração de volta é possível conforme as regras da tarifa, mediante taxa e diferença tarifária. Me informe a nova data desejada para a volta e retorno com os valores. | F8: Alteração voluntária com trecho de ida já voado. Cliente orientado; alteração só da volta, conforme regras da tarifa. | G8: Nome + Localizador | H8: Sim
A9: 7 | B9: Cancelamento | C9: Cancelamento voluntário - Dentro de 24 h da compra | D9: Solicitação > Aéreas > Cancelamento > Até 24 h da compra | E9: Em atenção à sua solicitação sobre o localizador {loc}, como a compra foi feita há menos de 24 horas e o voo é daqui a mais de 7 dias, o cancelamento é feito sem custo, com estorno integral dos pontos e das taxas. O pedido foi registrado sob o ticket {ticket}. Os pontos retornam à conta em até 48 horas e o valor das taxas é estornado na fatura do cartão em até duas faturas. | F9: Cancelamento voluntário dentro de 24 h da compra. Sem custos. Estorno integral solicitado. Ticket {ticket}. | G9: Nome + Localizador | H9: Não
A10: 8 | B10: Cancelamento | C10: Cancelamento voluntário - Fora de 24 h (com multa) | D10: Solicitação > Aéreas > Cancelamento > Com multa | E10: Em atenção à sua solicitação sobre o localizador {loc}, o cancelamento é possível com a multa prevista na tarifa. O valor residual retorna como pontos na sua conta. Me confirme se deseja seguir com o cancelamento nessas condições para eu registrar o pedido. | F10: Cancelamento voluntário fora de 24 h. Cliente orientado sobre multa e estorno em pontos. Aguardando confirmação. | G10: Nome + Localizador | H10: Não
A11: 9 | B11: Cancelamento | C11: Cancelamento excepcional - Volta (ida já utilizada) | D11: Solicitação > Aéreas > Cancelamento excepcional > Parcial | E11: Em atenção à sua solicitação sobre o localizador {loc}, registrei o pedido de cancelamento do trecho de volta. A solicitação segue como cancelamento parcial e passa por análise da companhia. O retorno sobre o valor a estornar chega em até 7 dias úteis no ticket {ticket}. | F11: Cancelamento excepcional parcial (volta), ida já utilizada. Pedido registrado para análise da companhia. Ticket {ticket}. | G11: Nome + Localizador + Ticket | H11: Sim
A12: 10 | B12: Cancelamento | C12: Cancelamento involuntário - Voo cancelado pela companhia | D12: Solicitação > Aéreas > Cancelamento involuntário > Reembolso | E12: Em atenção à sua solicitação sobre o localizador {loc}, confirmo que o voo foi cancelado pela companhia. Você tem direito a reacomodação sem custo ou reembolso integral, inclusive das taxas. Me diga qual opção prefere e eu registro agora. | F12: Cancelamento involuntário pela companhia. Cliente orientado sobre reacomodação ou reembolso integral. Aguardando escolha. | G12: Nome + Localizador | H12: Não
A13: 11 | B13: Cancelamento | C13: No-show - Cliente não compareceu | D13: Informação > Aéreas > No-show | E13: Em atenção à sua solicitação sobre o localizador {loc}, como não houve comparecimento ao embarque, a passagem foi marcada como no-show pela companhia. Nesse caso, as taxas de embarque podem ser reembolsadas; o valor da tarifa segue as regras do bilhete. Se quiser, abro o pedido de reembolso das taxas. | F13: No-show. Cliente orientado sobre reembolso de taxas de embarque e regras da tarifa. | G13: Nome + Localizador | H13: Não
A14: 12 | B14: Bagagem | C14: Bagagem - Compra de franquia adicional | D14: Informação > Aéreas > Bagagem > Franquia | E14: Em atenção à sua solicitação sobre o localizador {loc}, a franquia de bagagem despachada pode ser adquirida pelo site ou aplicativo da companhia, em Minhas Viagens, com valor menor que no aeroporto. Para compra com pontos, posso fazer por aqui: me informe quantas malas deseja adicionar. | F14: Bagagem, compra de franquia. Cliente orientado sobre compra pelo site/app ou com pontos pelo atendimento. | G14: Nome + Localizador | H14: Não
... A28: 26 | B28: Meteorologia | C28: Condições meteorológicas - Voo cancelado ou atrasado | D28: Informação > Aéreas > Meteorologia | E28: Em atenção à sua solicitação sobre o localizador {loc}, o voo foi afetado por condições meteorológicas, o que é tratado como caso fortuito pela regulamentação. A companhia oferece reacomodação no próximo voo disponível ou reembolso integral. Me diga qual opção prefere. | F28: Meteorologia, voo cancelado/atrasado. Cliente orientado sobre reacomodação ou reembolso. | G28: Nome + Localizador | H28: Não

Sheet Blocos
A1: BLOCOS DE TEXTO E REGRAS · tudo que entra na mensagem além do problema
B3: Saudação pelo horário | C3: Regra
B4: Agora | C4: =NOW()
B5: Saudação | C5: =IF(HOUR(C4)<12,"Bom dia",IF(HOUR(C4)<18,"Boa tarde","Boa noite"))
B6: Dia da semana | C6: =CHOOSE(WEEKDAY(C4,1),"domingo","segunda-feira","terça-feira","quarta-feira","quinta-feira","sexta-feira","sábado")
B7: Despedida | C7: =IF(WEEKDAY(C4,1)=6,"Desejo um ótimo fim de semana!",IF(WEEKDAY(C4,1)=2,"Desejo uma excelente semana!","Desejo um ótimo dia!"))
B9: Emojis (sorteio a cada recálculo) | C9: Lista
B10: abertura | C10: 😊
B11: abertura | C11: 👋
B12: abertura | C12: 🙂
B13: abertura | C13: ✨
B14: abertura | C14: 🛫
B15: fechamento | C15: 🤝
B16: fechamento | C16: 🙏
B17: fechamento | C17: 😉
B18: fechamento | C18: 👍
B19: fechamento | C19: 💙
B20: Emoji de abertura | C20: =INDEX($C$10:$C$14,RANDBETWEEN(1,5))
B21: Emoji de fechamento | C21: =INDEX($C$15:$C$19,RANDBETWEEN(1,5))
B23: Clube Horizonte · bloco por status | C23: Texto que entra na mensagem
B24: Elegível | C24: Aproveitando o contato: sua conta está elegível ao Clube Horizonte, que estende a validade dos seus pontos e dá desconto nas emissões. A adesão pode ser feita em Minha Conta > Clube.
B25: Assinante | C25: Vi que você é assinante do Clube Horizonte. Obrigado por fazer parte! Lembre que os pontos do Clube têm validade estendida enquanto a assinatura estiver ativa.
B26: Suspenso | C26: Notei que sua assinatura do Clube Horizonte está suspensa por pendência de pagamento. Para manter os benefícios, regularize em Minha Conta > Clube > Pagamento.
B27: Pendente | C27: Sua adesão ao Clube Horizonte está pendente de confirmação do pagamento. Assim que confirmada, os benefícios são liberados automaticamente.
B28: Não elegível
B31: Ida realizada · bloco (só em problemas que dependem da ida) | C31: Texto
B32: Sim | C32: Como o trecho de ida já foi utilizado, a solicitação vale apenas para o trecho de volta.
B33: Não | C33: Como nenhum trecho foi utilizado, a solicitação vale para a reserva completa (ida e volta).
B36: Categorias | C36: Validade dos pontos
B37: Bronze | C37: 24 meses
B38: Prata | C38: 36 meses
B39: Ouro | C39: 48 meses
B40: Diamante | C40: 60 meses
B42: Status do Clube (lista)
B43: Elegível
B44: Assinante
B45: Suspenso
B46: Pendente
B47: Não elegível
B49: Ida realizada (lista)
...

Sheet Aeroportos
A1: AEROPORTOS (IATA) E COMPANHIAS (fictícias)
A2: IATA | B2: Cidade / aeroporto | D2: Código | E2: Companhia | G2: Mês GDS | H2: Mês
A3: GRU | B3: São Paulo/Guarulhos | D3: HZ | E3: Aérea Horizonte | G3: JAN | H3: janeiro
A4: CGH | B4: São Paulo/Congonhas | D4: MR | E4: Meridiano Linhas Aéreas | G4: FEB | H4: fevereiro
A5: VCP | B5: Campinas/Viracopos | D5: VT | E5: Voe Vertente | G5: MAR | H5: março
A6: GIG | B6: Rio de Janeiro/Galeão | D6: AP | E6: Atlântico Pacífico Air | G6: APR | H6: abril
A7: SDU | B7: Rio de Janeiro/Santos Dumont | D7: NB | E7: Nimbus Europa | G7: MAY | H7: maio
A8: BSB | B8: Brasília | D8: KL | E8: Kestrel Lines | G8: JUN | H8: junho
A9: CWB | B9: Curitiba | G9: JUL | H9: julho
A10: POA | B10: Porto Alegre | G10: AUG | H10: agosto
A11: FLN | B11: Florianópolis | G11: SEP | H11: setembro
A12: CNF | B12: Belo Horizonte/Confins | G12: OCT | H12: outubro
A13: SSA | B13: Salvador | G13: NOV | H13: novembro
A14: REC | B14: Recife | G14: DEC | H14: dezembro
A15: FOR | B15: Fortaleza
A16: MAO | B16: Manaus
A17: BEL | B17: Belém
A18: CZS | B18: Cruzeiro do Sul
A19: GYN | B19: Goiânia
A20: NAT | B20: Natal
A21: MCZ | B21: Maceió
A22: VIX | B22: Vitória
A23: LIS | B23: Lisboa
A24: MAD | B24: Madri
A25: CDG | B25: Paris/Charles de Gaulle
A26: PRG | B26: Praga
... A37: MVD | B37: Montevidéu

Sheet Equipe
A1: EQUIPE · FRENTE DE E-MAIL (MEUS VOOS)
A2: Operador | B2: Supervisor | C2: Coordenador | D2: Turno | E2: Assinatura | F2: Operador (lista)
A3: Brenda Nunes | B3: Jaqueline Azevedo | C3: Livia Cardoso | D3: Manhã | E3: ="Brenda · Equipe Horizonte" | F3: =A3&" ("&D3&")"
A4: Caua Assunção | B4: Bruna Almeida | C4: Crhistoffer Miranda | D4: Manhã | E4: ="Caua · Equipe Horizonte" | F4: =A4&" ("&D4&")"
A5: Ian Nascimento | B5: Emir Anjos | C5: Crhistoffer Miranda | D5: Manhã | E5: ="Ian · Equipe Horizonte" | F5: =A5&" ("&D5&")"
A6: Nelson Costa | B6: Jaqueline Azevedo | C6: Livia Cardoso | D6: Manhã | E6: ="Nelson · Equipe Horizonte" | F6: =A6&" ("&D6&")"
A7: Nicolly Cunha | B7: Emir Anjos | C7: Crhistoffer Miranda | D7: Manhã | E7: ="Nicolly · Equipe Horizonte" | F7: =A7&" ("&D7&")"
A8: Vanyelle Vieira | B8: Emir Anjos | C8: Crhistoffer Miranda | D8: Manhã | E8: ="Vanyelle · Equipe Horizonte" | F8: =A8&" ("&D8&")"
A9: Julio Campos | B9: Jaqueline Azevedo | C9: Livia Cardoso | D9: Tarde | E9: ="Julio · Equipe Horizonte" | F9: =A9&" ("&D9&")"
A10: Leonardo Morais | B10: Jaqueline Azevedo | C10: Livia Cardoso | D10: Tarde | E10: ="Leonardo · Equipe Horizonte" | F10: =A10&" ("&D10&")"
A11: Marcella Dias | B11: Bruna Almeida | C11: Crhistoffer Miranda | D11: Tarde | E11: ="Marcella · Equipe Horizonte" | F11: =A11&" ("&D11&")"
A12: Nicole Nunes | B12: Bruna Almeida | C12: Crhistoffer Miranda | D12: Tarde | E12: ="Nicole · Equipe Horizonte" | F12: =A12&" ("&D12&")"
A13: Victor Anjos | B13: Bruna Almeida | C13: Crhistoffer Miranda | D13: Tarde | E13: ="Victor · Equipe Horizonte" | F13: =A13&" ("&D13&")"
A14: Wilma Dias | B14: Ualifer Azevedo | C14: Livia Cardoso | D14: Tarde | E14: ="Wilma · Equipe Horizonte" | F14: =A14&" ("&D14&")"
