Workbook

Sheet Home
A1: Qtd Atnd p/dia | C1: Dia | D1: Mês | E1: Ano | F1: Mês em texto | G1: Data Fixa | H1: Hora Fixa | I1: Link do Atendimento | J1: Problema do Cliente | K1: Observação | L1: U1 | N1: Contact Type | O1: Link KB | P1: Etapa | Q1: Informação Extra | R1: Obs Usuário | S1: Obs Motorista | T1: Resp p/Cliente | V1: Status Tkt | W1: Somente Link | X1: Sigla | Z1: SC | AA1: CR | AB1: XX | AC1: PS | AE1: Hora
G2: xx | H2: xx | I2: xx | J2: xx | K2: xx
A3: =IF(G3="","",IF(G3=G2,"",COUNTIF($G$3:$G$976,G3))) | C3: =IF(G3="","",DAY(G3)) | D3: =IF(G3="","",MONTH(G3)) | E3: =IF(G3="","",YEAR(G3)) | F3: =IF(G3="","",CHOOSE(MONTH(G3),"Janeiro","Fevereiro","Março","Abril","Maio","Junho","Julho","Agosto","Setembro","Outubro","Novembro","Dezembro")) | G3: 46054 | H3: 0.002974537 | I3: https://docs.google.com/spreadsheets/d/1ZiCGoPjLCjuYvujDTXK9Ixbth3tekiLtFBzBrGjPCr4/edit?gid=0#gid=0 | J3: Taxa de Limpeza - [TXL] | L3: FALSE | N3: =IF($J3="","",IFERROR(INDEX(B!$F$2:$F$61,MATCH($J3,B!$E$2:$E$61,0))&"","")) | O3: =IF($J3="","",IFERROR(INDEX(B!$G$2:$G$61,MATCH($J3,B!$E$2:$E$61,0))&"","")) | P3: =IF($J3="","",IFERROR(INDEX(B!$H$2:$H$61,MATCH($J3,B!$E$2:$E$61,0))&"","")) | Q3: =IF($J3="","",IFERROR(INDEX(B!$I$2:$I$61,MATCH($J3,B!$E$2:$E$61,0))&"","")) | R3: =IF($J3="","",IFERROR(INDEX(B!$J$2:$J$61,MATCH($J3,B!$E$2:$E$61,0))&"","")) | S3: =IF($J3="","",IFERROR(INDEX(B!$K$2:$K$61,MATCH($J3,B!$E$2:$E$61,0))&"","")) | T3: =IF($J3="","",IFERROR(INDEX(B!$L$2:$L$61,MATCH($J3,B!$E$2:$E$61,0))&"","")) | V3: =IF($J3="","",IFERROR(INDEX(B!$M$2:$M$61,MATCH($J3,B!$E$2:$E$61,0))&"","")) | W3: =IF(I3="","",IFERROR(MID(I3,FIND("/d/",I3)+3,FIND("/edit",I3)-FIND("/d/",I3)-3),I3)) | X3: =IF($J3="","",IFERROR(INDEX(B!$C$2:$C$61,MATCH($J3,B!$E$2:$E$61,0))&"","")) | Z3: =IF($J3="",FALSE,ISNUMBER(SEARCH("scout",$K3))) | AA3: =IF($J3="",FALSE,IFERROR(INDEX(B!$N$2:$N$61,MATCH($J3,B!$E$2:$E$61,0))="Sim",FALSE)) | AB3: =IF($J3="",FALSE,LEFT($X3,2)="XX") | AC3: =IF($J3="",FALSE,IFERROR(INDEX(B!$P$2:$P$61,MATCH($J3,B!$E$2:$E$61,0))="Sim",FALSE)) | AE3: =IF(H3="","",HOUR(H3))
A4: =IF(G4="","",IF(G4=G3,"",COUNTIF($G$3:$G$976,G4))) | C4: =IF(G4="","",DAY(G4)) | D4: =IF(G4="","",MONTH(G4)) | E4: =IF(G4="","",YEAR(G4)) | F4: =IF(G4="","",CHOOSE(MONTH(G4),"Janeiro","Fevereiro","Março","Abril","Maio","Junho","Julho","Agosto","Setembro","Outubro","Novembro","Dezembro")) | G4: 46054 | H4: 0.010428241 | I4: https://docs.google.com/spreadsheets/d/1ZiCGoPjLCjuYvujDTXK9Ixbth3tekiLtFBzBrGjPCr4/edit?gid=0#gid=0 | J4: Taxa de Limpeza - [TXL] | L4: FALSE | N4: =IF($J4="","",IFERROR(INDEX(B!$F$2:$F$61,MATCH($J4,B!$E$2:$E$61,0))&"","")) | O4: =IF($J4="","",IFERROR(INDEX(B!$G$2:$G$61,MATCH($J4,B!$E$2:$E$61,0))&"","")) | P4: =IF($J4="","",IFERROR(INDEX(B!$H$2:$H$61,MATCH($J4,B!$E$2:$E$61,0))&"","")) | Q4: =IF($J4="","",IFERROR(INDEX(B!$I$2:$I$61,MATCH($J4,B!$E$2:$E$61,0))&"","")) | R4: =IF($J4="","",IFERROR(INDEX(B!$J$2:$J$61,MATCH($J4,B!$E$2:$E$61,0))&"","")) | S4: =IF($J4="","",IFERROR(INDEX(B!$K$2:$K$61,MATCH($J4,B!$E$2:$E$61,0))&"","")) | T4: =IF($J4="","",IFERROR(INDEX(B!$L$2:$L$61,MATCH($J4,B!$E$2:$E$61,0))&"","")) | V4: =IF($J4="","",IFERROR(INDEX(B!$M$2:$M$61,MATCH($J4,B!$E$2:$E$61,0))&"","")) | W4: =IF(I4="","",IFERROR(MID(I4,FIND("/d/",I4)+3,FIND("/edit",I4)-FIND("/d/",I4)-3),I4)) | X4: =IF($J4="","",IFERROR(INDEX(B!$C$2:$C$61,MATCH($J4,B!$E$2:$E$61,0))&"","")) | Z4: =IF($J4="",FALSE,ISNUMBER(SEARCH("scout",$K4))) | AA4: =IF($J4="",FALSE,IFERROR(INDEX(B!$N$2:$N$61,MATCH($J4,B!$E$2:$E$61,0))="Sim",FALSE)) | AB4: =IF($J4="",FALSE,LEFT($X4,2)="XX") | AC4: =IF($J4="",FALSE,IFERROR(INDEX(B!$P$2:$P$61,MATCH($J4,B!$E$2:$E$61,0))="Sim",FALSE)) | AE4: =IF(H4="","",HOUR(H4))
A5: =IF(G5="","",IF(G5=G4,"",COUNTIF($G$3:$G$976,G5))) | C5: =IF(G5="","",DAY(G5)) | D5: =IF(G5="","",MONTH(G5)) | E5: =IF(G5="","",YEAR(G5)) | F5: =IF(G5="","",CHOOSE(MONTH(G5),"Janeiro","Fevereiro","Março","Abril","Maio","Junho","Julho","Agosto","Setembro","Outubro","Novembro","Dezembro")) | G5: 46054 | H5: 0.012893519 | I5: https://docs.google.com/spreadsheets/d/1ZiCGoPjLCjuYvujDTXK9Ixbth3tekiLtFBzBrGjPCr4/edit?gid=0#gid=0 | J5: Taxa de Cancelamento Cobrada Corretamente - [TXCO] | L5: FALSE | N5: =IF($J5="","",IFERROR(INDEX(B!$F$2:$F$61,MATCH($J5,B!$E$2:$E$61,0))&"","")) | O5: =IF($J5="","",IFERROR(INDEX(B!$G$2:$G$61,MATCH($J5,B!$E$2:$E$61,0))&"","")) | P5: =IF($J5="","",IFERROR(INDEX(B!$H$2:$H$61,MATCH($J5,B!$E$2:$E$61,0))&"","")) | Q5: =IF($J5="","",IFERROR(INDEX(B!$I$2:$I$61,MATCH($J5,B!$E$2:$E$61,0))&"","")) | R5: =IF($J5="","",IFERROR(INDEX(B!$J$2:$J$61,MATCH($J5,B!$E$2:$E$61,0))&"","")) | S5: =IF($J5="","",IFERROR(INDEX(B!$K$2:$K$61,MATCH($J5,B!$E$2:$E$61,0))&"","")) | T5: =IF($J5="","",IFERROR(INDEX(B!$L$2:$L$61,MATCH($J5,B!$E$2:$E$61,0))&"","")) | V5: =IF($J5="","",IFERROR(INDEX(B!$M$2:$M$61,MATCH($J5,B!$E$2:$E$61,0))&"","")) | W5: =IF(I5="","",IFERROR(MID(I5,FIND("/d/",I5)+3,FIND("/edit",I5)-FIND("/d/",I5)-3),I5)) | X5: =IF($J5="","",IFERROR(INDEX(B!$C$2:$C$61,MATCH($J5,B!$E$2:$E$61,0))&"","")) | Z5: =IF($J5="",FALSE,ISNUMBER(SEARCH("scout",$K5))) | AA5: =IF($J5="",FALSE,IFERROR(INDEX(B!$N$2:$N$61,MATCH($J5,B!$E$2:$E$61,0))="Sim",FALSE)) | AB5: =IF($J5="",FALSE,LEFT($X5,2)="XX") | AC5: =IF($J5="",FALSE,IFERROR(INDEX(B!$P$2:$P$61,MATCH($J5,B!$E$2:$E$61,0))="Sim",FALSE)) | AE5: =IF(H5="","",HOUR(H5))
A6: =IF(G6="","",IF(G6=G5,"",COUNTIF($G$3:$G$976,G6))) | C6: =IF(G6="","",DAY(G6)) | D6: =IF(G6="","",MONTH(G6)) | E6: =IF(G6="","",YEAR(G6)) | F6: =IF(G6="","",CHOOSE(MONTH(G6),"Janeiro","Fevereiro","Março","Abril","Maio","Junho","Julho","Agosto","Setembro","Outubro","Novembro","Dezembro")) | G6: 46054 | H6: 0.013240741 | I6: https://docs.google.com/spreadsheets/d/1ZiCGoPjLCjuYvujDTXK9Ixbth3tekiLtFBzBrGjPCr4/edit?gid=0#gid=0 | J6: Taxa de Limpeza, Reembolsado ao cliente - [TXLR] | L6: FALSE | N6: =IF($J6="","",IFERROR(INDEX(B!$F$2:$F$61,MATCH($J6,B!$E$2:$E$61,0))&"","")) | O6: =IF($J6="","",IFERROR(INDEX(B!$G$2:$G$61,MATCH($J6,B!$E$2:$E$61,0))&"","")) | P6: =IF($J6="","",IFERROR(INDEX(B!$H$2:$H$61,MATCH($J6,B!$E$2:$E$61,0))&"","")) | Q6: =IF($J6="","",IFERROR(INDEX(B!$I$2:$I$61,MATCH($J6,B!$E$2:$E$61,0))&"","")) | R6: =IF($J6="","",IFERROR(INDEX(B!$J$2:$J$61,MATCH($J6,B!$E$2:$E$61,0))&"","")) | S6: =IF($J6="","",IFERROR(INDEX(B!$K$2:$K$61,MATCH($J6,B!$E$2:$E$61,0))&"","")) | T6: =IF($J6="","",IFERROR(INDEX(B!$L$2:$L$61,MATCH($J6,B!$E$2:$E$61,0))&"","")) | V6: =IF($J6="","",IFERROR(INDEX(B!$M$2:$M$61,MATCH($J6,B!$E$2:$E$61,0))&"","")) | W6: =IF(I6="","",IFERROR(MID(I6,FIND("/d/",I6)+3,FIND("/edit",I6)-FIND("/d/",I6)-3),I6)) | X6: =IF($J6="","",IFERROR(INDEX(B!$C$2:$C$61,MATCH($J6,B!$E$2:$E$61,0))&"","")) | Z6: =IF($J6="",FALSE,ISNUMBER(SEARCH("scout",$K6))) | AA6: =IF($J6="",FALSE,IFERROR(INDEX(B!$N$2:$N$61,MATCH($J6,B!$E$2:$E$61,0))="Sim",FALSE)) | AB6: =IF($J6="",FALSE,LEFT($X6,2)="XX") | AC6: =IF($J6="",FALSE,IFERROR(INDEX(B!$P$2:$P$61,MATCH($J6,B!$E$2:$E$61,0))="Sim",FALSE)) | AE6: =IF(H6="","",HOUR(H6))
A7: =IF(G7="","",IF(G7=G6,"",COUNTIF($G$3:$G$976,G7))) | C7: =IF(G7="","",DAY(G7)) | D7: =IF(G7="","",MONTH(G7)) | E7: =IF(G7="","",YEAR(G7)) | F7: =IF(G7="","",CHOOSE(MONTH(G7),"Janeiro","Fevereiro","Março","Abril","Maio","Junho","Julho","Agosto","Setembro","Outubro","Novembro","Dezembro")) | G7: 46054 | H7: 0.036215278 | I7: https://docs.google.com/spreadsheets/d/1ZiCGoPjLCjuYvujDTXK9Ixbth3tekiLtFBzBrGjPCr4/edit?gid=0#gid=0 | J7: Não houve Taxa de Cancelamento - [NTX] | L7: FALSE | N7: =IF($J7="","",IFERROR(INDEX(B!$F$2:$F$61,MATCH($J7,B!$E$2:$E$61,0))&"","")) | O7: =IF($J7="","",IFERROR(INDEX(B!$G$2:$G$61,MATCH($J7,B!$E$2:$E$61,0))&"","")) | P7: =IF($J7="","",IFERROR(INDEX(B!$H$2:$H$61,MATCH($J7,B!$E$2:$E$61,0))&"","")) | Q7: =IF($J7="","",IFERROR(INDEX(B!$I$2:$I$61,MATCH($J7,B!$E$2:$E$61,0))&"","")) | R7: =IF($J7="","",IFERROR(INDEX(B!$J$2:$J$61,MATCH($J7,B!$E$2:$E$61,0))&"","")) | S7: =IF($J7="","",IFERROR(INDEX(B!$K$2:$K$61,MATCH($J7,B!$E$2:$E$61,0))&"","")) | T7: =IF($J7="","",IFERROR(INDEX(B!$L$2:$L$61,MATCH($J7,B!$E$2:$E$61,0))&"","")) | V7: =IF($J7="","",IFERROR(INDEX(B!$M$2:$M$61,MATCH($J7,B!$E$2:$E$61,0))&"","")) | W7: =IF(I7="","",IFERROR(MID(I7,FIND("/d/",I7)+3,FIND("/edit",I7)-FIND("/d/",I7)-3),I7)) | X7: =IF($J7="","",IFERROR(INDEX(B!$C$2:$C$61,MATCH($J7,B!$E$2:$E$61,0))&"","")) | Z7: =IF($J7="",FALSE,ISNUMBER(SEARCH("scout",$K7))) | AA7: =IF($J7="",FALSE,IFERROR(INDEX(B!$N$2:$N$61,MATCH($J7,B!$E$2:$E$61,0))="Sim",FALSE)) | AB7: =IF($J7="",FALSE,LEFT($X7,2)="XX") | AC7: =IF($J7="",FALSE,IFERROR(INDEX(B!$P$2:$P$61,MATCH($J7,B!$E$2:$E$61,0))="Sim",FALSE)) | AE7: =IF(H7="","",HOUR(H7))
A8: =IF(G8="","",IF(G8=G7,"",COUNTIF($G$3:$G$976,G8))) | C8: =IF(G8="","",DAY(G8)) | D8: =IF(G8="","",MONTH(G8)) | E8: =IF(G8="","",YEAR(G8)) | F8: =IF(G8="","",CHOOSE(MONTH(G8),"Janeiro","Fevereiro","Março","Abril","Maio","Junho","Julho","Agosto","Setembro","Outubro","Novembro","Dezembro")) | G8: 46054 | H8: 0.039236111 | I8: https://docs.google.com/spreadsheets/d/1ZiCGoPjLCjuYvujDTXK9Ixbth3tekiLtFBzBrGjPCr4/edit?gid=0#gid=0 | J8: Overpaid, Excede o limite Com comprovante - [OPEC] | L8: FALSE | N8: =IF($J8="","",IFERROR(INDEX(B!$F$2:$F$61,MATCH($J8,B!$E$2:$E$61,0))&"","")) | O8: =IF($J8="","",IFERROR(INDEX(B!$G$2:$G$61,MATCH($J8,B!$E$2:$E$61,0))&"","")) | P8: =IF($J8="","",IFERROR(INDEX(B!$H$2:$H$61,MATCH($J8,B!$E$2:$E$61,0))&"","")) | Q8: =IF($J8="","",IFERROR(INDEX(B!$I$2:$I$61,MATCH($J8,B!$E$2:$E$61,0))&"","")) | R8: =IF($J8="","",IFERROR(INDEX(B!$J$2:$J$61,MATCH($J8,B!$E$2:$E$61,0))&"","")) | S8: =IF($J8="","",IFERROR(INDEX(B!$K$2:$K$61,MATCH($J8,B!$E$2:$E$61,0))&"","")) | T8: =IF($J8="","",IFERROR(INDEX(B!$L$2:$L$61,MATCH($J8,B!$E$2:$E$61,0))&"","")) | V8: =IF($J8="","",IFERROR(INDEX(B!$M$2:$M$61,MATCH($J8,B!$E$2:$E$61,0))&"","")) | W8: =IF(I8="","",IFERROR(MID(I8,FIND("/d/",I8)+3,FIND("/edit",I8)-FIND("/d/",I8)-3),I8)) | X8: =IF($J8="","",IFERROR(INDEX(B!$C$2:$C$61,MATCH($J8,B!$E$2:$E$61,0))&"","")) | Z8: =IF($J8="",FALSE,ISNUMBER(SEARCH("scout",$K8))) | AA8: =IF($J8="",FALSE,IFERROR(INDEX(B!$N$2:$N$61,MATCH($J8,B!$E$2:$E$61,0))="Sim",FALSE)) | AB8: =IF($J8="",FALSE,LEFT($X8,2)="XX") | AC8: =IF($J8="",FALSE,IFERROR(INDEX(B!$P$2:$P$61,MATCH($J8,B!$E$2:$E$61,0))="Sim",FALSE)) | AE8: =IF(H8="","",HOUR(H8))
A9: =IF(G9="","",IF(G9=G8,"",COUNTIF($G$3:$G$976,G9))) | C9: =IF(G9="","",DAY(G9)) | D9: =IF(G9="","",MONTH(G9)) | E9: =IF(G9="","",YEAR(G9)) | F9: =IF(G9="","",CHOOSE(MONTH(G9),"Janeiro","Fevereiro","Março","Abril","Maio","Junho","Julho","Agosto","Setembro","Outubro","Novembro","Dezembro")) | G9: 46054 | H9: 0.041435185 | I9: https://docs.google.com/spreadsheets/d/1ZiCGoPjLCjuYvujDTXK9Ixbth3tekiLtFBzBrGjPCr4/edit?gid=0#gid=0 | J9: Transferência de LOB (Geral não especificado) - [TI] | L9: FALSE | N9: =IF($J9="","",IFERROR(INDEX(B!$F$2:$F$61,MATCH($J9,B!$E$2:$E$61,0))&"","")) | O9: =IF($J9="","",IFERROR(INDEX(B!$G$2:$G$61,MATCH($J9,B!$E$2:$E$61,0))&"","")) | P9: =IF($J9="","",IFERROR(INDEX(B!$H$2:$H$61,MATCH($J9,B!$E$2:$E$61,0))&"","")) | Q9: =IF($J9="","",IFERROR(INDEX(B!$I$2:$I$61,MATCH($J9,B!$E$2:$E$61,0))&"","")) | R9: =IF($J9="","",IFERROR(INDEX(B!$J$2:$J$61,MATCH($J9,B!$E$2:$E$61,0))&"","")) | S9: =IF($J9="","",IFERROR(INDEX(B!$K$2:$K$61,MATCH($J9,B!$E$2:$E$61,0))&"","")) | T9: =IF($J9="","",IFERROR(INDEX(B!$L$2:$L$61,MATCH($J9,B!$E$2:$E$61,0))&"","")) | V9: =IF($J9="","",IFERROR(INDEX(B!$M$2:$M$61,MATCH($J9,B!$E$2:$E$61,0))&"","")) | W9: =IF(I9="","",IFERROR(MID(I9,FIND("/d/",I9)+3,FIND("/edit",I9)-FIND("/d/",I9)-3),I9)) | X9: =IF($J9="","",IFERROR(INDEX(B!$C$2:$C$61,MATCH($J9,B!$E$2:$E$61,0))&"","")) | Z9: =IF($J9="",FALSE,ISNUMBER(SEARCH("scout",$K9))) | AA9: =IF($J9="",FALSE,IFERROR(INDEX(B!$N$2:$N$61,MATCH($J9,B!$E$2:$E$61,0))="Sim",FALSE)) | AB9: =IF($J9="",FALSE,LEFT($X9,2)="XX") | AC9: =IF($J9="",FALSE,IFERROR(INDEX(B!$P$2:$P$61,MATCH($J9,B!$E$2:$E$61,0))="Sim",FALSE)) | AE9: =IF(H9="","",HOUR(H9))
A10: =IF(G10="","",IF(G10=G9,"",COUNTIF($G$3:$G$976,G10))) | C10: =IF(G10="","",DAY(G10)) | D10: =IF(G10="","",MONTH(G10)) | E10: =IF(G10="","",YEAR(G10)) | F10: =IF(G10="","",CHOOSE(MONTH(G10),"Janeiro","Fevereiro","Março","Abril","Maio","Junho","Julho","Agosto","Setembro","Outubro","Novembro","Dezembro")) | G10: 46054 | H10: 0.051805556 | I10: https://docs.google.com/spreadsheets/d/1ZiCGoPjLCjuYvujDTXK9Ixbth3tekiLtFBzBrGjPCr4/edit?gid=0#gid=0 | J10: Overpaid, Excede o limite, Sem comprovante - [OPEN] | L10: FALSE | N10: =IF($J10="","",IFERROR(INDEX(B!$F$2:$F$61,MATCH($J10,B!$E$2:$E$61,0))&"","")) | O10: =IF($J10="","",IFERROR(INDEX(B!$G$2:$G$61,MATCH($J10,B!$E$2:$E$61,0))&"","")) | P10: =IF($J10="","",IFERROR(INDEX(B!$H$2:$H$61,MATCH($J10,B!$E$2:$E$61,0))&"","")) | Q10: =IF($J10="","",IFERROR(INDEX(B!$I$2:$I$61,MATCH($J10,B!$E$2:$E$61,0))&"","")) | R10: =IF($J10="","",IFERROR(INDEX(B!$J$2:$J$61,MATCH($J10,B!$E$2:$E$61,0))&"","")) | S10: =IF($J10="","",IFERROR(INDEX(B!$K$2:$K$61,MATCH($J10,B!$E$2:$E$61,0))&"","")) | T10: =IF($J10="","",IFERROR(INDEX(B!$L$2:$L$61,MATCH($J10,B!$E$2:$E$61,0))&"","")) | V10: =IF($J10="","",IFERROR(INDEX(B!$M$2:$M$61,MATCH($J10,B!$E$2:$E$61,0))&"","")) | W10: =IF(I10="","",IFERROR(MID(I10,FIND("/d/",I10)+3,FIND("/edit",I10)-FIND("/d/",I10)-3),I10)) | X10: =IF($J10="","",IFERROR(INDEX(B!$C$2:$C$61,MATCH($J10,B!$E$2:$E$61,0))&"","")) | Z10: =IF($J10="",FALSE,ISNUMBER(SEARCH("scout",$K10))) | AA10: =IF($J10="",FALSE,IFERROR(INDEX(B!$N$2:$N$61,MATCH($J10,B!$E$2:$E$61,0))="Sim",FALSE)) | AB10: =IF($J10="",FALSE,LEFT($X10,2)="XX") | AC10: =IF($J10="",FALSE,IFERROR(INDEX(B!$P$2:$P$61,MATCH($J10,B!$E$2:$E$61,0))="Sim",FALSE)) | AE10: =IF(H10="","",HOUR(H10))
A11: =IF(G11="","",IF(G11=G10,"",COUNTIF($G$3:$G$976,G11))) | C11: =IF(G11="","",DAY(G11)) | D11: =IF(G11="","",MONTH(G11)) | E11: =IF(G11="","",YEAR(G11)) | F11: =IF(G11="","",CHOOSE(MONTH(G11),"Janeiro","Fevereiro","Março","Abril","Maio","Junho","Julho","Agosto","Setembro","Outubro","Novembro","Dezembro")) | G11: 46054 | H11: 0.052731481 | I11: https://docs.google.com/spreadsheets/d/1ZiCGoPjLCjuYvujDTXK9Ixbth3tekiLtFBzBrGjPCr4/edit?gid=0#gid=0 | J11: Transferência de LOB (Driver) - [TIDV] | L11: FALSE | N11: =IF($J11="","",IFERROR(INDEX(B!$F$2:$F$61,MATCH($J11,B!$E$2:$E$61,0))&"","")) | O11: =IF($J11="","",IFERROR(INDEX(B!$G$2:$G$61,MATCH($J11,B!$E$2:$E$61,0))&"","")) | P11: =IF($J11="","",IFERROR(INDEX(B!$H$2:$H$61,MATCH($J11,B!$E$2:$E$61,0))&"","")) | Q11: =IF($J11="","",IFERROR(INDEX(B!$I$2:$I$61,MATCH($J11,B!$E$2:$E$61,0))&"","")) | R11: =IF($J11="","",IFERROR(INDEX(B!$J$2:$J$61,MATCH($J11,B!$E$2:$E$61,0))&"","")) | S11: =IF($J11="","",IFERROR(INDEX(B!$K$2:$K$61,MATCH($J11,B!$E$2:$E$61,0))&"","")) | T11: =IF($J11="","",IFERROR(INDEX(B!$L$2:$L$61,MATCH($J11,B!$E$2:$E$61,0))&"","")) | V11: =IF($J11="","",IFERROR(INDEX(B!$M$2:$M$61,MATCH($J11,B!$E$2:$E$61,0))&"","")) | W11: =IF(I11="","",IFERROR(MID(I11,FIND("/d/",I11)+3,FIND("/edit",I11)-FIND("/d/",I11)-3),I11)) | X11: =IF($J11="","",IFERROR(INDEX(B!$C$2:$C$61,MATCH($J11,B!$E$2:$E$61,0))&"","")) | Z11: =IF($J11="",FALSE,ISNUMBER(SEARCH("scout",$K11))) | AA11: =IF($J11="",FALSE,IFERROR(INDEX(B!$N$2:$N$61,MATCH($J11,B!$E$2:$E$61,0))="Sim",FALSE)) | AB11: =IF($J11="",FALSE,LEFT($X11,2)="XX") | AC11: =IF($J11="",FALSE,IFERROR(INDEX(B!$P$2:$P$61,MATCH($J11,B!$E$2:$E$61,0))="Sim",FALSE)) | AE11: =IF(H11="","",HOUR(H11))
A12: =IF(G12="","",IF(G12=G11,"",COUNTIF($G$3:$G$976,G12))) | C12: =IF(G12="","",DAY(G12)) | D12: =IF(G12="","",MONTH(G12)) | E12: =IF(G12="","",YEAR(G12)) | F12: =IF(G12="","",CHOOSE(MONTH(G12),"Janeiro","Fevereiro","Março","Abril","Maio","Junho","Julho","Agosto","Setembro","Outubro","Novembro","Dezembro")) | G12: 46054 | H12: 0.054583333 | I12: https://docs.google.com/spreadsheets/d/1ZiCGoPjLCjuYvujDTXK9Ixbth3tekiLtFBzBrGjPCr4/edit?gid=0#gid=0 | J12: Pushback - [XX] | K12: Scout | L12: FALSE | N12: =IF($J12="","",IFERROR(INDEX(B!$F$2:$F$61,MATCH($J12,B!$E$2:$E$61,0))&"","")) | O12: =IF($J12="","",IFERROR(INDEX(B!$G$2:$G$61,MATCH($J12,B!$E$2:$E$61,0))&"","")) | P12: =IF($J12="","",IFERROR(INDEX(B!$H$2:$H$61,MATCH($J12,B!$E$2:$E$61,0))&"","")) | Q12: =IF($J12="","",IFERROR(INDEX(B!$I$2:$I$61,MATCH($J12,B!$E$2:$E$61,0))&"","")) | R12: =IF($J12="","",IFERROR(INDEX(B!$J$2:$J$61,MATCH($J12,B!$E$2:$E$61,0))&"","")) | S12: =IF($J12="","",IFERROR(INDEX(B!$K$2:$K$61,MATCH($J12,B!$E$2:$E$61,0))&"","")) | T12: =IF($J12="","",IFERROR(INDEX(B!$L$2:$L$61,MATCH($J12,B!$E$2:$E$61,0))&"","")) | V12: =IF($J12="","",IFERROR(INDEX(B!$M$2:$M$61,MATCH($J12,B!$E$2:$E$61,0))&"","")) | W12: =IF(I12="","",IFERROR(MID(I12,FIND("/d/",I12)+3,FIND("/edit",I12)-FIND("/d/",I12)-3),I12)) | X12: =IF($J12="","",IFERROR(INDEX(B!$C$2:$C$61,MATCH($J12,B!$E$2:$E$61,0))&"","")) | Z12: =IF($J12="",FALSE,ISNUMBER(SEARCH("scout",$K12))) | AA12: =IF($J12="",FALSE,IFERROR(INDEX(B!$N$2:$N$61,MATCH($J12,B!$E$2:$E$61,0))="Sim",FALSE)) | AB12: =IF($J12="",FALSE,LEFT($X12,2)="XX") | AC12: =IF($J12="",FALSE,IFERROR(INDEX(B!$P$2:$P$61,MATCH($J12,B!$E$2:$E$61,0))="Sim",FALSE)) | AE12: =IF(H12="","",HOUR(H12))
A13: =IF(G13="","",IF(G13=G12,"",COUNTIF($G$3:$G$976,G13))) | C13: =IF(G13="","",DAY(G13)) | D13: =IF(G13="","",MONTH(G13)) | E13: =IF(G13="","",YEAR(G13)) | F13: =IF(G13="","",CHOOSE(MONTH(G13),"Janeiro","Fevereiro","Março","Abril","Maio","Junho","Julho","Agosto","Setembro","Outubro","Novembro","Dezembro")) | G13: 46054 | H13: 0.060486111 | I13: https://docs.google.com/spreadsheets/d/1ZiCGoPjLCjuYvujDTXK9Ixbth3tekiLtFBzBrGjPCr4/edit?gid=0#gid=0 | J13: Trajeto Ruim - [TR] | L13: FALSE | N13: =IF($J13="","",IFERROR(INDEX(B!$F$2:$F$61,MATCH($J13,B!$E$2:$E$61,0))&"","")) | O13: =IF($J13="","",IFERROR(INDEX(B!$G$2:$G$61,MATCH($J13,B!$E$2:$E$61,0))&"","")) | P13: =IF($J13="","",IFERROR(INDEX(B!$H$2:$H$61,MATCH($J13,B!$E$2:$E$61,0))&"","")) | Q13: =IF($J13="","",IFERROR(INDEX(B!$I$2:$I$61,MATCH($J13,B!$E$2:$E$61,0))&"","")) | R13: =IF($J13="","",IFERROR(INDEX(B!$J$2:$J$61,MATCH($J13,B!$E$2:$E$61,0))&"","")) | S13: =IF($J13="","",IFERROR(INDEX(B!$K$2:$K$61,MATCH($J13,B!$E$2:$E$61,0))&"","")) | T13: =IF($J13="","",IFERROR(INDEX(B!$L$2:$L$61,MATCH($J13,B!$E$2:$E$61,0))&"","")) | V13: =IF($J13="","",IFERROR(INDEX(B!$M$2:$M$61,MATCH($J13,B!$E$2:$E$61,0))&"","")) | W13: =IF(I13="","",IFERROR(MID(I13,FIND("/d/",I13)+3,FIND("/edit",I13)-FIND("/d/",I13)-3),I13)) | X13: =IF($J13="","",IFERROR(INDEX(B!$C$2:$C$61,MATCH($J13,B!$E$2:$E$61,0))&"","")) | Z13: =IF($J13="",FALSE,ISNUMBER(SEARCH("scout",$K13))) | AA13: =IF($J13="",FALSE,IFERROR(INDEX(B!$N$2:$N$61,MATCH($J13,B!$E$2:$E$61,0))="Sim",FALSE)) | AB13: =IF($J13="",FALSE,LEFT($X13,2)="XX") | AC13: =IF($J13="",FALSE,IFERROR(INDEX(B!$P$2:$P$61,MATCH($J13,B!$E$2:$E$61,0))="Sim",FALSE)) | AE13: =IF(H13="","",HOUR(H13))
A14: =IF(G14="","",IF(G14=G13,"",COUNTIF($G$3:$G$976,G14))) | C14: =IF(G14="","",DAY(G14)) | D14: =IF(G14="","",MONTH(G14)) | E14: =IF(G14="","",YEAR(G14)) | F14: =IF(G14="","",CHOOSE(MONTH(G14),"Janeiro","Fevereiro","Março","Abril","Maio","Junho","Julho","Agosto","Setembro","Outubro","Novembro","Dezembro")) | G14: 46054 | H14: 0.060821759 | I14: https://docs.google.com/spreadsheets/d/1ZiCGoPjLCjuYvujDTXK9Ixbth3tekiLtFBzBrGjPCr4/edit?gid=0#gid=0 | J14: Taxa de Limpeza - [TXL] | K14: Scout | L14: FALSE | N14: =IF($J14="","",IFERROR(INDEX(B!$F$2:$F$61,MATCH($J14,B!$E$2:$E$61,0))&"","")) | O14: =IF($J14="","",IFERROR(INDEX(B!$G$2:$G$61,MATCH($J14,B!$E$2:$E$61,0))&"","")) | P14: =IF($J14="","",IFERROR(INDEX(B!$H$2:$H$61,MATCH($J14,B!$E$2:$E$61,0))&"","")) | Q14: =IF($J14="","",IFERROR(INDEX(B!$I$2:$I$61,MATCH($J14,B!$E$2:$E$61,0))&"","")) | R14: =IF($J14="","",IFERROR(INDEX(B!$J$2:$J$61,MATCH($J14,B!$E$2:$E$61,0))&"","")) | S14: =IF($J14="","",IFERROR(INDEX(B!$K$2:$K$61,MATCH($J14,B!$E$2:$E$61,0))&"","")) | T14: =IF($J14="","",IFERROR(INDEX(B!$L$2:$L$61,MATCH($J14,B!$E$2:$E$61,0))&"","")) | V14: =IF($J14="","",IFERROR(INDEX(B!$M$2:$M$61,MATCH($J14,B!$E$2:$E$61,0))&"","")) | W14: =IF(I14="","",IFERROR(MID(I14,FIND("/d/",I14)+3,FIND("/edit",I14)-FIND("/d/",I14)-3),I14)) | X14: =IF($J14="","",IFERROR(INDEX(B!$C$2:$C$61,MATCH($J14,B!$E$2:$E$61,0))&"","")) | Z14: =IF($J14="",FALSE,ISNUMBER(SEARCH("scout",$K14))) | AA14: =IF($J14="",FALSE,IFERROR(INDEX(B!$N$2:$N$61,MATCH($J14,B!$E$2:$E$61,0))="Sim",FALSE)) | AB14: =IF($J14="",FALSE,LEFT($X14,2)="XX") | AC14: =IF($J14="",FALSE,IFERROR(INDEX(B!$P$2:$P$61,MATCH($J14,B!$E$2:$E$61,0))="Sim",FALSE)) | AE14: =IF(H14="","",HOUR(H14))
A15: =IF(G15="","",IF(G15=G14,"",COUNTIF($G$3:$G$976,G15))) | C15: =IF(G15="","",DAY(G15)) | D15: =IF(G15="","",MONTH(G15)) | E15: =IF(G15="","",YEAR(G15)) | F15: =IF(G15="","",CHOOSE(MONTH(G15),"Janeiro","Fevereiro","Março","Abril","Maio","Junho","Julho","Agosto","Setembro","Outubro","Novembro","Dezembro")) | G15: 46054 | H15: 0.064791667 | I15: https://docs.google.com/spreadsheets/d/1ZiCGoPjLCjuYvujDTXK9Ixbth3tekiLtFBzBrGjPCr4/edit?gid=0#gid=0 | J15: Pushback - [XX] | K15: Scout | L15: FALSE | N15: =IF($J15="","",IFERROR(INDEX(B!$F$2:$F$61,MATCH($J15,B!$E$2:$E$61,0))&"","")) | O15: =IF($J15="","",IFERROR(INDEX(B!$G$2:$G$61,MATCH($J15,B!$E$2:$E$61,0))&"","")) | P15: =IF($J15="","",IFERROR(INDEX(B!$H$2:$H$61,MATCH($J15,B!$E$2:$E$61,0))&"","")) | Q15: =IF($J15="","",IFERROR(INDEX(B!$I$2:$I$61,MATCH($J15,B!$E$2:$E$61,0))&"","")) | R15: =IF($J15="","",IFERROR(INDEX(B!$J$2:$J$61,MATCH($J15,B!$E$2:$E$61,0))&"","")) | S15: =IF($J15="","",IFERROR(INDEX(B!$K$2:$K$61,MATCH($J15,B!$E$2:$E$61,0))&"","")) | T15: =IF($J15="","",IFERROR(INDEX(B!$L$2:$L$61,MATCH($J15,B!$E$2:$E$61,0))&"","")) | V15: =IF($J15="","",IFERROR(INDEX(B!$M$2:$M$61,MATCH($J15,B!$E$2:$E$61,0))&"","")) | W15: =IF(I15="","",IFERROR(MID(I15,FIND("/d/",I15)+3,FIND("/edit",I15)-FIND("/d/",I15)-3),I15)) | X15: =IF($J15="","",IFERROR(INDEX(B!$C$2:$C$61,MATCH($J15,B!$E$2:$E$61,0))&"","")) | Z15: =IF($J15="",FALSE,ISNUMBER(SEARCH("scout",$K15))) | AA15: =IF($J15="",FALSE,IFERROR(INDEX(B!$N$2:$N$61,MATCH($J15,B!$E$2:$E$61,0))="Sim",FALSE)) | AB15: =IF($J15="",FALSE,LEFT($X15,2)="XX") | AC15: =IF($J15="",FALSE,IFERROR(INDEX(B!$P$2:$P$61,MATCH($J15,B!$E$2:$E$61,0))="Sim",FALSE)) | AE15: =IF(H15="","",HOUR(H15))
A16: =IF(G16="","",IF(G16=G15,"",COUNTIF($G$3:$G$976,G16))) | C16: =IF(G16="","",DAY(G16)) | D16: =IF(G16="","",MONTH(G16)) | E16: =IF(G16="","",YEAR(G16)) | F16: =IF(G16="","",CHOOSE(MONTH(G16),"Janeiro","Fevereiro","Março","Abril","Maio","Junho","Julho","Agosto","Setembro","Outubro","Novembro","Dezembro")) | G16: 46054 | H16: 0.068240741 | I16: https://docs.google.com/spreadsheets/d/1ZiCGoPjLCjuYvujDTXK9Ixbth3tekiLtFBzBrGjPCr4/edit?gid=0#gid=0 | J16: Pushback - [XX] | L16: FALSE | N16: =IF($J16="","",IFERROR(INDEX(B!$F$2:$F$61,MATCH($J16,B!$E$2:$E$61,0))&"","")) | O16: =IF($J16="","",IFERROR(INDEX(B!$G$2:$G$61,MATCH($J16,B!$E$2:$E$61,0))&"","")) | P16: =IF($J16="","",IFERROR(INDEX(B!$H$2:$H$61,MATCH($J16,B!$E$2:$E$61,0))&"","")) | Q16: =IF($J16="","",IFERROR(INDEX(B!$I$2:$I$61,MATCH($J16,B!$E$2:$E$61,0))&"","")) | R16: =IF($J16="","",IFERROR(INDEX(B!$J$2:$J$61,MATCH($J16,B!$E$2:$E$61,0))&"","")) | S16: =IF($J16="","",IFERROR(INDEX(B!$K$2:$K$61,MATCH($J16,B!$E$2:$E$61,0))&"","")) | T16: =IF($J16="","",IFERROR(INDEX(B!$L$2:$L$61,MATCH($J16,B!$E$2:$E$61,0))&"","")) | V16: =IF($J16="","",IFERROR(INDEX(B!$M$2:$M$61,MATCH($J16,B!$E$2:$E$61,0))&"","")) | W16: =IF(I16="","",IFERROR(MID(I16,FIND("/d/",I16)+3,FIND("/edit",I16)-FIND("/d/",I16)-3),I16)) | X16: =IF($J16="","",IFERROR(INDEX(B!$C$2:$C$61,MATCH($J16,B!$E$2:$E$61,0))&"","")) | Z16: =IF($J16="",FALSE,ISNUMBER(SEARCH("scout",$K16))) | AA16: =IF($J16="",FALSE,IFERROR(INDEX(B!$N$2:$N$61,MATCH($J16,B!$E$2:$E$61,0))="Sim",FALSE)) | AB16: =IF($J16="",FALSE,LEFT($X16,2)="XX") | AC16: =IF($J16="",FALSE,IFERROR(INDEX(B!$P$2:$P$61,MATCH($J16,B!$E$2:$E$61,0))="Sim",FALSE)) | AE16: =IF(H16="","",HOUR(H16))
A17: =IF(G17="","",IF(G17=G16,"",COUNTIF($G$3:$G$976,G17))) | C17: =IF(G17="","",DAY(G17)) | D17: =IF(G17="","",MONTH(G17)) | E17: =IF(G17="","",YEAR(G17)) | F17: =IF(G17="","",CHOOSE(MONTH(G17),"Janeiro","Fevereiro","Março","Abril","Maio","Junho","Julho","Agosto","Setembro","Outubro","Novembro","Dezembro")) | G17: 46054 | H17: 0.071689815 | I17: https://docs.google.com/spreadsheets/d/1ZiCGoPjLCjuYvujDTXK9Ixbth3tekiLtFBzBrGjPCr4/edit?gid=0#gid=0 | J17: Taxa de Cancelamento - [TXC] | K17: Scout | L17: FALSE | N17: =IF($J17="","",IFERROR(INDEX(B!$F$2:$F$61,MATCH($J17,B!$E$2:$E$61,0))&"","")) | O17: =IF($J17="","",IFERROR(INDEX(B!$G$2:$G$61,MATCH($J17,B!$E$2:$E$61,0))&"","")) | P17: =IF($J17="","",IFERROR(INDEX(B!$H$2:$H$61,MATCH($J17,B!$E$2:$E$61,0))&"","")) | Q17: =IF($J17="","",IFERROR(INDEX(B!$I$2:$I$61,MATCH($J17,B!$E$2:$E$61,0))&"","")) | R17: =IF($J17="","",IFERROR(INDEX(B!$J$2:$J$61,MATCH($J17,B!$E$2:$E$61,0))&"","")) | S17: =IF($J17="","",IFERROR(INDEX(B!$K$2:$K$61,MATCH($J17,B!$E$2:$E$61,0))&"","")) | T17: =IF($J17="","",IFERROR(INDEX(B!$L$2:$L$61,MATCH($J17,B!$E$2:$E$61,0))&"","")) | V17: =IF($J17="","",IFERROR(INDEX(B!$M$2:$M$61,MATCH($J17,B!$E$2:$E$61,0))&"","")) | W17: =IF(I17="","",IFERROR(MID(I17,FIND("/d/",I17)+3,FIND("/edit",I17)-FIND("/d/",I17)-3),I17)) | X17: =IF($J17="","",IFERROR(INDEX(B!$C$2:$C$61,MATCH($J17,B!$E$2:$E$61,0))&"","")) | Z17: =IF($J17="",FALSE,ISNUMBER(SEARCH("scout",$K17))) | AA17: =IF($J17="",FALSE,IFERROR(INDEX(B!$N$2:$N$61,MATCH($J17,B!$E$2:$E$61,0))="Sim",FALSE)) | AB17: =IF($J17="",FALSE,LEFT($X17,2)="XX") | AC17: =IF($J17="",FALSE,IFERROR(INDEX(B!$P$2:$P$61,MATCH($J17,B!$E$2:$E$61,0))="Sim",FALSE)) | AE17: =IF(H17="","",HOUR(H17))
A18: =IF(G18="","",IF(G18=G17,"",COUNTIF($G$3:$G$976,G18))) | C18: =IF(G18="","",DAY(G18)) | D18: =IF(G18="","",MONTH(G18)) | E18: =IF(G18="","",YEAR(G18)) | F18: =IF(G18="","",CHOOSE(MONTH(G18),"Janeiro","Fevereiro","Março","Abril","Maio","Junho","Julho","Agosto","Setembro","Outubro","Novembro","Dezembro")) | G18: 46054 | H18: 0.075856481 | I18: https://docs.google.com/spreadsheets/d/1ZiCGoPjLCjuYvujDTXK9Ixbth3tekiLtFBzBrGjPCr4/edit?gid=0#gid=0 | J18: Taxa de Cancelamento - [TXC] | L18: FALSE | N18: =IF($J18="","",IFERROR(INDEX(B!$F$2:$F$61,MATCH($J18,B!$E$2:$E$61,0))&"","")) | O18: =IF($J18="","",IFERROR(INDEX(B!$G$2:$G$61,MATCH($J18,B!$E$2:$E$61,0))&"","")) | P18: =IF($J18="","",IFERROR(INDEX(B!$H$2:$H$61,MATCH($J18,B!$E$2:$E$61,0))&"","")) | Q18: =IF($J18="","",IFERROR(INDEX(B!$I$2:$I$61,MATCH($J18,B!$E$2:$E$61,0))&"","")) | R18: =IF($J18="","",IFERROR(INDEX(B!$J$2:$J$61,MATCH($J18,B!$E$2:$E$61,0))&"","")) | S18: =IF($J18="","",IFERROR(INDEX(B!$K$2:$K$61,MATCH($J18,B!$E$2:$E$61,0))&"","")) | T18: =IF($J18="","",IFERROR(INDEX(B!$L$2:$L$61,MATCH($J18,B!$E$2:$E$61,0))&"","")) | V18: =IF($J18="","",IFERROR(INDEX(B!$M$2:$M$61,MATCH($J18,B!$E$2:$E$61,0))&"","")) | W18: =IF(I18="","",IFERROR(MID(I18,FIND("/d/",I18)+3,FIND("/edit",I18)-FIND("/d/",I18)-3),I18)) | X18: =IF($J18="","",IFERROR(INDEX(B!$C$2:$C$61,MATCH($J18,B!$E$2:$E$61,0))&"","")) | Z18: =IF($J18="",FALSE,ISNUMBER(SEARCH("scout",$K18))) | AA18: =IF($J18="",FALSE,IFERROR(INDEX(B!$N$2:$N$61,MATCH($J18,B!$E$2:$E$61,0))="Sim",FALSE)) | AB18: =IF($J18="",FALSE,LEFT($X18,2)="XX") | AC18: =IF($J18="",FALSE,IFERROR(INDEX(B!$P$2:$P$61,MATCH($J18,B!$E$2:$E$61,0))="Sim",FALSE)) | AE18: =IF(H18="","",HOUR(H18))
A19: =IF(G19="","",IF(G19=G18,"",COUNTIF($G$3:$G$976,G19))) | C19: =IF(G19="","",DAY(G19)) | D19: =IF(G19="","",MONTH(G19)) | E19: =IF(G19="","",YEAR(G19)) | F19: =IF(G19="","",CHOOSE(MONTH(G19),"Janeiro","Fevereiro","Março","Abril","Maio","Junho","Julho","Agosto","Setembro","Outubro","Novembro","Dezembro")) | G19: 46054 | H19: 0.076111111 | I19: https://docs.google.com/spreadsheets/d/1ZiCGoPjLCjuYvujDTXK9Ixbth3tekiLtFBzBrGjPCr4/edit?gid=0#gid=0 | J19: Transferência de LOB (Accounts) - [TIAC] | K19: Scout | L19: FALSE | N19: =IF($J19="","",IFERROR(INDEX(B!$F$2:$F$61,MATCH($J19,B!$E$2:$E$61,0))&"","")) | O19: =IF($J19="","",IFERROR(INDEX(B!$G$2:$G$61,MATCH($J19,B!$E$2:$E$61,0))&"","")) | P19: =IF($J19="","",IFERROR(INDEX(B!$H$2:$H$61,MATCH($J19,B!$E$2:$E$61,0))&"","")) | Q19: =IF($J19="","",IFERROR(INDEX(B!$I$2:$I$61,MATCH($J19,B!$E$2:$E$61,0))&"","")) | R19: =IF($J19="","",IFERROR(INDEX(B!$J$2:$J$61,MATCH($J19,B!$E$2:$E$61,0))&"","")) | S19: =IF($J19="","",IFERROR(INDEX(B!$K$2:$K$61,MATCH($J19,B!$E$2:$E$61,0))&"","")) | T19: =IF($J19="","",IFERROR(INDEX(B!$L$2:$L$61,MATCH($J19,B!$E$2:$E$61,0))&"","")) | V19: =IF($J19="","",IFERROR(INDEX(B!$M$2:$M$61,MATCH($J19,B!$E$2:$E$61,0))&"","")) | W19: =IF(I19="","",IFERROR(MID(I19,FIND("/d/",I19)+3,FIND("/edit",I19)-FIND("/d/",I19)-3),I19)) | X19: =IF($J19="","",IFERROR(INDEX(B!$C$2:$C$61,MATCH($J19,B!$E$2:$E$61,0))&"","")) | Z19: =IF($J19="",FALSE,ISNUMBER(SEARCH("scout",$K19))) | AA19: =IF($J19="",FALSE,IFERROR(INDEX(B!$N$2:$N$61,MATCH($J19,B!$E$2:$E$61,0))="Sim",FALSE)) | AB19: =IF($J19="",FALSE,LEFT($X19,2)="XX") | AC19: =IF($J19="",FALSE,IFERROR(INDEX(B!$P$2:$P$61,MATCH($J19,B!$E$2:$E$61,0))="Sim",FALSE)) | AE19: =IF(H19="","",HOUR(H19))
A20: =IF(G20="","",IF(G20=G19,"",COUNTIF($G$3:$G$976,G20))) | C20: =IF(G20="","",DAY(G20)) | D20: =IF(G20="","",MONTH(G20)) | E20: =IF(G20="","",YEAR(G20)) | F20: =IF(G20="","",CHOOSE(MONTH(G20),"Janeiro","Fevereiro","Março","Abril","Maio","Junho","Julho","Agosto","Setembro","Outubro","Novembro","Dezembro")) | G20: 46054 | H20: 0.079884259 | I20: https://docs.google.com/spreadsheets/d/1ZiCGoPjLCjuYvujDTXK9Ixbth3tekiLtFBzBrGjPCr4/edit?gid=0#gid=0 | J20: Transferência de LOB (Lost Items) - [TILI] | K20: Scout | L20: FALSE | N20: =IF($J20="","",IFERROR(INDEX(B!$F$2:$F$61,MATCH($J20,B!$E$2:$E$61,0))&"","")) | O20: =IF($J20="","",IFERROR(INDEX(B!$G$2:$G$61,MATCH($J20,B!$E$2:$E$61,0))&"","")) | P20: =IF($J20="","",IFERROR(INDEX(B!$H$2:$H$61,MATCH($J20,B!$E$2:$E$61,0))&"","")) | Q20: =IF($J20="","",IFERROR(INDEX(B!$I$2:$I$61,MATCH($J20,B!$E$2:$E$61,0))&"","")) | R20: =IF($J20="","",IFERROR(INDEX(B!$J$2:$J$61,MATCH($J20,B!$E$2:$E$61,0))&"","")) | S20: =IF($J20="","",IFERROR(INDEX(B!$K$2:$K$61,MATCH($J20,B!$E$2:$E$61,0))&"","")) | T20: =IF($J20="","",IFERROR(INDEX(B!$L$2:$L$61,MATCH($J20,B!$E$2:$E$61,0))&"","")) | V20: =IF($J20="","",IFERROR(INDEX(B!$M$2:$M$61,MATCH($J20,B!$E$2:$E$61,0))&"","")) | W20: =IF(I20="","",IFERROR(MID(I20,FIND("/d/",I20)+3,FIND("/edit",I20)-FIND("/d/",I20)-3),I20)) | X20: =IF($J20="","",IFERROR(INDEX(B!$C$2:$C$61,MATCH($J20,B!$E$2:$E$61,0))&"","")) | Z20: =IF($J20="",FALSE,ISNUMBER(SEARCH("scout",$K20))) | AA20: =IF($J20="",FALSE,IFERROR(INDEX(B!$N$2:$N$61,MATCH($J20,B!$E$2:$E$61,0))="Sim",FALSE)) | AB20: =IF($J20="",FALSE,LEFT($X20,2)="XX") | AC20: =IF($J20="",FALSE,IFERROR(INDEX(B!$P$2:$P$61,MATCH($J20,B!$E$2:$E$61,0))="Sim",FALSE)) | AE20: =IF(H20="","",HOUR(H20))
A21: =IF(G21="","",IF(G21=G20,"",COUNTIF($G$3:$G$976,G21))) | C21: =IF(G21="","",DAY(G21)) | D21: =IF(G21="","",MONTH(G21)) | E21: =IF(G21="","",YEAR(G21)) | F21: =IF(G21="","",CHOOSE(MONTH(G21),"Janeiro","Fevereiro","Março","Abril","Maio","Junho","Julho","Agosto","Setembro","Outubro","Novembro","Dezembro")) | G21: 46054 | H21: 0.091388889 | I21: https://docs.google.com/spreadsheets/d/1ZiCGoPjLCjuYvujDTXK9Ixbth3tekiLtFBzBrGjPCr4/edit?gid=0#gid=0 | J21: Overpaid, Excede o limite Com comprovante - [OPEC] | L21: FALSE | N21: =IF($J21="","",IFERROR(INDEX(B!$F$2:$F$61,MATCH($J21,B!$E$2:$E$61,0))&"","")) | O21: =IF($J21="","",IFERROR(INDEX(B!$G$2:$G$61,MATCH($J21,B!$E$2:$E$61,0))&"","")) | P21: =IF($J21="","",IFERROR(INDEX(B!$H$2:$H$61,MATCH($J21,B!$E$2:$E$61,0))&"","")) | Q21: =IF($J21="","",IFERROR(INDEX(B!$I$2:$I$61,MATCH($J21,B!$E$2:$E$61,0))&"","")) | R21: =IF($J21="","",IFERROR(INDEX(B!$J$2:$J$61,MATCH($J21,B!$E$2:$E$61,0))&"","")) | S21: =IF($J21="","",IFERROR(INDEX(B!$K$2:$K$61,MATCH($J21,B!$E$2:$E$61,0))&"","")) | T21: =IF($J21="","",IFERROR(INDEX(B!$L$2:$L$61,MATCH($J21,B!$E$2:$E$61,0))&"","")) | V21: =IF($J21="","",IFERROR(INDEX(B!$M$2:$M$61,MATCH($J21,B!$E$2:$E$61,0))&"","")) | W21: =IF(I21="","",IFERROR(MID(I21,FIND("/d/",I21)+3,FIND("/edit",I21)-FIND("/d/",I21)-3),I21)) | X21: =IF($J21="","",IFERROR(INDEX(B!$C$2:$C$61,MATCH($J21,B!$E$2:$E$61,0))&"","")) | Z21: =IF($J21="",FALSE,ISNUMBER(SEARCH("scout",$K21))) | AA21: =IF($J21="",FALSE,IFERROR(INDEX(B!$N$2:$N$61,MATCH($J21,B!$E$2:$E$61,0))="Sim",FALSE)) | AB21: =IF($J21="",FALSE,LEFT($X21,2)="XX") | AC21: =IF($J21="",FALSE,IFERROR(INDEX(B!$P$2:$P$61,MATCH($J21,B!$E$2:$E$61,0))="Sim",FALSE)) | AE21: =IF(H21="","",HOUR(H21))
A22: =IF(G22="","",IF(G22=G21,"",COUNTIF($G$3:$G$976,G22))) | C22: =IF(G22="","",DAY(G22)) | D22: =IF(G22="","",MONTH(G22)) | E22: =IF(G22="","",YEAR(G22)) | F22: =IF(G22="","",CHOOSE(MONTH(G22),"Janeiro","Fevereiro","Março","Abril","Maio","Junho","Julho","Agosto","Setembro","Outubro","Novembro","Dezembro")) | G22: 46054 | H22: 0.099907407 | I22: https://docs.google.com/spreadsheets/d/1ZiCGoPjLCjuYvujDTXK9Ixbth3tekiLtFBzBrGjPCr4/edit?gid=0#gid=0 | J22: Transferência de LOB (Geral não especificado) - [TI] | L22: FALSE | N22: =IF($J22="","",IFERROR(INDEX(B!$F$2:$F$61,MATCH($J22,B!$E$2:$E$61,0))&"","")) | O22: =IF($J22="","",IFERROR(INDEX(B!$G$2:$G$61,MATCH($J22,B!$E$2:$E$61,0))&"","")) | P22: =IF($J22="","",IFERROR(INDEX(B!$H$2:$H$61,MATCH($J22,B!$E$2:$E$61,0))&"","")) | Q22: =IF($J22="","",IFERROR(INDEX(B!$I$2:$I$61,MATCH($J22,B!$E$2:$E$61,0))&"","")) | R22: =IF($J22="","",IFERROR(INDEX(B!$J$2:$J$61,MATCH($J22,B!$E$2:$E$61,0))&"","")) | S22: =IF($J22="","",IFERROR(INDEX(B!$K$2:$K$61,MATCH($J22,B!$E$2:$E$61,0))&"","")) | T22: =IF($J22="","",IFERROR(INDEX(B!$L$2:$L$61,MATCH($J22,B!$E$2:$E$61,0))&"","")) | V22: =IF($J22="","",IFERROR(INDEX(B!$M$2:$M$61,MATCH($J22,B!$E$2:$E$61,0))&"","")) | W22: =IF(I22="","",IFERROR(MID(I22,FIND("/d/",I22)+3,FIND("/edit",I22)-FIND("/d/",I22)-3),I22)) | X22: =IF($J22="","",IFERROR(INDEX(B!$C$2:$C$61,MATCH($J22,B!$E$2:$E$61,0))&"","")) | Z22: =IF($J22="",FALSE,ISNUMBER(SEARCH("scout",$K22))) | AA22: =IF($J22="",FALSE,IFERROR(INDEX(B!$N$2:$N$61,MATCH($J22,B!$E$2:$E$61,0))="Sim",FALSE)) | AB22: =IF($J22="",FALSE,LEFT($X22,2)="XX") | AC22: =IF($J22="",FALSE,IFERROR(INDEX(B!$P$2:$P$61,MATCH($J22,B!$E$2:$E$61,0))="Sim",FALSE)) | AE22: =IF(H22="","",HOUR(H22))
A23: =IF(G23="","",IF(G23=G22,"",COUNTIF($G$3:$G$976,G23))) | C23: =IF(G23="","",DAY(G23)) | D23: =IF(G23="","",MONTH(G23)) | E23: =IF(G23="","",YEAR(G23)) | F23: =IF(G23="","",CHOOSE(MONTH(G23),"Janeiro","Fevereiro","Março","Abril","Maio","Junho","Julho","Agosto","Setembro","Outubro","Novembro","Dezembro")) | G23: 46054 | H23: 0.10021991 | I23: https://docs.google.com/spreadsheets/d/1ZiCGoPjLCjuYvujDTXK9Ixbth3tekiLtFBzBrGjPCr4/edit?gid=0#gid=0 | J23: No Need Response (Não precisa de resposta) - [NRN] | L23: FALSE | N23: =IF($J23="","",IFERROR(INDEX(B!$F$2:$F$61,MATCH($J23,B!$E$2:$E$61,0))&"","")) | O23: =IF($J23="","",IFERROR(INDEX(B!$G$2:$G$61,MATCH($J23,B!$E$2:$E$61,0))&"","")) | P23: =IF($J23="","",IFERROR(INDEX(B!$H$2:$H$61,MATCH($J23,B!$E$2:$E$61,0))&"","")) | Q23: =IF($J23="","",IFERROR(INDEX(B!$I$2:$I$61,MATCH($J23,B!$E$2:$E$61,0))&"","")) | R23: =IF($J23="","",IFERROR(INDEX(B!$J$2:$J$61,MATCH($J23,B!$E$2:$E$61,0))&"","")) | S23: =IF($J23="","",IFERROR(INDEX(B!$K$2:$K$61,MATCH($J23,B!$E$2:$E$61,0))&"","")) | T23: =IF($J23="","",IFERROR(INDEX(B!$L$2:$L$61,MATCH($J23,B!$E$2:$E$61,0))&"","")) | V23: =IF($J23="","",IFERROR(INDEX(B!$M$2:$M$61,MATCH($J23,B!$E$2:$E$61,0))&"","")) | W23: =IF(I23="","",IFERROR(MID(I23,FIND("/d/",I23)+3,FIND("/edit",I23)-FIND("/d/",I23)-3),I23)) | X23: =IF($J23="","",IFERROR(INDEX(B!$C$2:$C$61,MATCH($J23,B!$E$2:$E$61,0))&"","")) | Z23: =IF($J23="",FALSE,ISNUMBER(SEARCH("scout",$K23))) | AA23: =IF($J23="",FALSE,IFERROR(INDEX(B!$N$2:$N$61,MATCH($J23,B!$E$2:$E$61,0))="Sim",FALSE)) | AB23: =IF($J23="",FALSE,LEFT($X23,2)="XX") | AC23: =IF($J23="",FALSE,IFERROR(INDEX(B!$P$2:$P$61,MATCH($J23,B!$E$2:$E$61,0))="Sim",FALSE)) | AE23: =IF(H23="","",HOUR(H23))
A24: =IF(G24="","",IF(G24=G23,"",COUNTIF($G$3:$G$976,G24))) | C24: =IF(G24="","",DAY(G24)) | D24: =IF(G24="","",MONTH(G24)) | E24: =IF(G24="","",YEAR(G24)) | F24: =IF(G24="","",CHOOSE(MONTH(G24),"Janeiro","Fevereiro","Março","Abril","Maio","Junho","Julho","Agosto","Setembro","Outubro","Novembro","Dezembro")) | G24: 46054 | H24: 0.10150463 | I24: https://docs.google.com/spreadsheets/d/1ZiCGoPjLCjuYvujDTXK9Ixbth3tekiLtFBzBrGjPCr4/edit?gid=0#gid=0 | J24: Evento Raro - [ER] | L24: FALSE | N24: =IF($J24="","",IFERROR(INDEX(B!$F$2:$F$61,MATCH($J24,B!$E$2:$E$61,0))&"","")) | O24: =IF($J24="","",IFERROR(INDEX(B!$G$2:$G$61,MATCH($J24,B!$E$2:$E$61,0))&"","")) | P24: =IF($J24="","",IFERROR(INDEX(B!$H$2:$H$61,MATCH($J24,B!$E$2:$E$61,0))&"","")) | Q24: =IF($J24="","",IFERROR(INDEX(B!$I$2:$I$61,MATCH($J24,B!$E$2:$E$61,0))&"","")) | R24: =IF($J24="","",IFERROR(INDEX(B!$J$2:$J$61,MATCH($J24,B!$E$2:$E$61,0))&"","")) | S24: =IF($J24="","",IFERROR(INDEX(B!$K$2:$K$61,MATCH($J24,B!$E$2:$E$61,0))&"","")) | T24: =IF($J24="","",IFERROR(INDEX(B!$L$2:$L$61,MATCH($J24,B!$E$2:$E$61,0))&"","")) | V24: =IF($J24="","",IFERROR(INDEX(B!$M$2:$M$61,MATCH($J24,B!$E$2:$E$61,0))&"","")) | W24: =IF(I24="","",IFERROR(MID(I24,FIND("/d/",I24)+3,FIND("/edit",I24)-FIND("/d/",I24)-3),I24)) | X24: =IF($J24="","",IFERROR(INDEX(B!$C$2:$C$61,MATCH($J24,B!$E$2:$E$61,0))&"","")) | Z24: =IF($J24="",FALSE,ISNUMBER(SEARCH("scout",$K24))) | AA24: =IF($J24="",FALSE,IFERROR(INDEX(B!$N$2:$N$61,MATCH($J24,B!$E$2:$E$61,0))="Sim",FALSE)) | AB24: =IF($J24="",FALSE,LEFT($X24,2)="XX") | AC24: =IF($J24="",FALSE,IFERROR(INDEX(B!$P$2:$P$61,MATCH($J24,B!$E$2:$E$61,0))="Sim",FALSE)) | AE24: =IF(H24="","",HOUR(H24))
A25: =IF(G25="","",IF(G25=G24,"",COUNTIF($G$3:$G$976,G25))) | C25: =IF(G25="","",DAY(G25)) | D25: =IF(G25="","",MONTH(G25)) | E25: =IF(G25="","",YEAR(G25)) | F25: =IF(G25="","",CHOOSE(MONTH(G25),"Janeiro","Fevereiro","Março","Abril","Maio","Junho","Julho","Agosto","Setembro","Outubro","Novembro","Dezembro")) | G25: 46054 | H25: 0.10462963 | I25: https://docs.google.com/spreadsheets/d/1ZiCGoPjLCjuYvujDTXK9Ixbth3tekiLtFBzBrGjPCr4/edit?gid=0#gid=0 | J25: Taxa de Limpeza, Sem ajustes - [TXLO] | L25: FALSE | N25: =IF($J25="","",IFERROR(INDEX(B!$F$2:$F$61,MATCH($J25,B!$E$2:$E$61,0))&"","")) | O25: =IF($J25="","",IFERROR(INDEX(B!$G$2:$G$61,MATCH($J25,B!$E$2:$E$61,0))&"","")) | P25: =IF($J25="","",IFERROR(INDEX(B!$H$2:$H$61,MATCH($J25,B!$E$2:$E$61,0))&"","")) | Q25: =IF($J25="","",IFERROR(INDEX(B!$I$2:$I$61,MATCH($J25,B!$E$2:$E$61,0))&"","")) | R25: =IF($J25="","",IFERROR(INDEX(B!$J$2:$J$61,MATCH($J25,B!$E$2:$E$61,0))&"","")) | S25: =IF($J25="","",IFERROR(INDEX(B!$K$2:$K$61,MATCH($J25,B!$E$2:$E$61,0))&"","")) | T25: =IF($J25="","",IFERROR(INDEX(B!$L$2:$L$61,MATCH($J25,B!$E$2:$E$61,0))&"","")) | V25: =IF($J25="","",IFERROR(INDEX(B!$M$2:$M$61,MATCH($J25,B!$E$2:$E$61,0))&"","")) | W25: =IF(I25="","",IFERROR(MID(I25,FIND("/d/",I25)+3,FIND("/edit",I25)-FIND("/d/",I25)-3),I25)) | X25: =IF($J25="","",IFERROR(INDEX(B!$C$2:$C$61,MATCH($J25,B!$E$2:$E$61,0))&"","")) | Z25: =IF($J25="",FALSE,ISNUMBER(SEARCH("scout",$K25))) | AA25: =IF($J25="",FALSE,IFERROR(INDEX(B!$N$2:$N$61,MATCH($J25,B!$E$2:$E$61,0))="Sim",FALSE)) | AB25: =IF($J25="",FALSE,LEFT($X25,2)="XX") | AC25: =IF($J25="",FALSE,IFERROR(INDEX(B!$P$2:$P$61,MATCH($J25,B!$E$2:$E$61,0))="Sim",FALSE)) | AE25: =IF(H25="","",HOUR(H25))
A26: =IF(G26="","",IF(G26=G25,"",COUNTIF($G$3:$G$976,G26))) | C26: =IF(G26="","",DAY(G26)) | D26: =IF(G26="","",MONTH(G26)) | E26: =IF(G26="","",YEAR(G26)) | F26: =IF(G26="","",CHOOSE(MONTH(G26),"Janeiro","Fevereiro","Março","Abril","Maio","Junho","Julho","Agosto","Setembro","Outubro","Novembro","Dezembro")) | G26: 46054 | H26: 0.11381944 | I26: https://docs.google.com/spreadsheets/d/1ZiCGoPjLCjuYvujDTXK9Ixbth3tekiLtFBzBrGjPCr4/edit?gid=0#gid=0 | J26: Viagem Calculada Incorretamente - [VCI] | L26: FALSE | N26: =IF($J26="","",IFERROR(INDEX(B!$F$2:$F$61,MATCH($J26,B!$E$2:$E$61,0))&"","")) | O26: =IF($J26="","",IFERROR(INDEX(B!$G$2:$G$61,MATCH($J26,B!$E$2:$E$61,0))&"","")) | P26: =IF($J26="","",IFERROR(INDEX(B!$H$2:$H$61,MATCH($J26,B!$E$2:$E$61,0))&"","")) | Q26: =IF($J26="","",IFERROR(INDEX(B!$I$2:$I$61,MATCH($J26,B!$E$2:$E$61,0))&"","")) | R26: =IF($J26="","",IFERROR(INDEX(B!$J$2:$J$61,MATCH($J26,B!$E$2:$E$61,0))&"","")) | S26: =IF($J26="","",IFERROR(INDEX(B!$K$2:$K$61,MATCH($J26,B!$E$2:$E$61,0))&"","")) | T26: =IF($J26="","",IFERROR(INDEX(B!$L$2:$L$61,MATCH($J26,B!$E$2:$E$61,0))&"","")) | V26: =IF($J26="","",IFERROR(INDEX(B!$M$2:$M$61,MATCH($J26,B!$E$2:$E$61,0))&"","")) | W26: =IF(I26="","",IFERROR(MID(I26,FIND("/d/",I26)+3,FIND("/edit",I26)-FIND("/d/",I26)-3),I26)) | X26: =IF($J26="","",IFERROR(INDEX(B!$C$2:$C$61,MATCH($J26,B!$E$2:$E$61,0))&"","")) | Z26: =IF($J26="",FALSE,ISNUMBER(SEARCH("scout",$K26))) | AA26: =IF($J26="",FALSE,IFERROR(INDEX(B!$N$2:$N$61,MATCH($J26,B!$E$2:$E$61,0))="Sim",FALSE)) | AB26: =IF($J26="",FALSE,LEFT($X26,2)="XX") | AC26: =IF($J26="",FALSE,IFERROR(INDEX(B!$P$2:$P$61,MATCH($J26,B!$E$2:$E$61,0))="Sim",FALSE)) | AE26: =IF(H26="","",HOUR(H26))
A27: =IF(G27="","",IF(G27=G26,"",COUNTIF($G$3:$G$976,G27))) | C27: =IF(G27="","",DAY(G27)) | D27: =IF(G27="","",MONTH(G27)) | E27: =IF(G27="","",YEAR(G27)) | F27: =IF(G27="","",CHOOSE(MONTH(G27),"Janeiro","Fevereiro","Março","Abril","Maio","Junho","Julho","Agosto","Setembro","Outubro","Novembro","Dezembro")) | G27: 46054 | H27: 0.11385417 | I27: https://docs.google.com/spreadsheets/d/1ZiCGoPjLCjuYvujDTXK9Ixbth3tekiLtFBzBrGjPCr4/edit?gid=0#gid=0 | J27: Overpaid, Não excede o limite, Sem comprovante - [OPNN] | L27: FALSE | N27: =IF($J27="","",IFERROR(INDEX(B!$F$2:$F$61,MATCH($J27,B!$E$2:$E$61,0))&"","")) | O27: =IF($J27="","",IFERROR(INDEX(B!$G$2:$G$61,MATCH($J27,B!$E$2:$E$61,0))&"","")) | P27: =IF($J27="","",IFERROR(INDEX(B!$H$2:$H$61,MATCH($J27,B!$E$2:$E$61,0))&"","")) | Q27: =IF($J27="","",IFERROR(INDEX(B!$I$2:$I$61,MATCH($J27,B!$E$2:$E$61,0))&"","")) | R27: =IF($J27="","",IFERROR(INDEX(B!$J$2:$J$61,MATCH($J27,B!$E$2:$E$61,0))&"","")) | S27: =IF($J27="","",IFERROR(INDEX(B!$K$2:$K$61,MATCH($J27,B!$E$2:$E$61,0))&"","")) | T27: =IF($J27="","",IFERROR(INDEX(B!$L$2:$L$61,MATCH($J27,B!$E$2:$E$61,0))&"","")) | V27: =IF($J27="","",IFERROR(INDEX(B!$M$2:$M$61,MATCH($J27,B!$E$2:$E$61,0))&"","")) | W27: =IF(I27="","",IFERROR(MID(I27,FIND("/d/",I27)+3,FIND("/edit",I27)-FIND("/d/",I27)-3),I27)) | X27: =IF($J27="","",IFERROR(INDEX(B!$C$2:$C$61,MATCH($J27,B!$E$2:$E$61,0))&"","")) | Z27: =IF($J27="",FALSE,ISNUMBER(SEARCH("scout",$K27))) | AA27: =IF($J27="",FALSE,IFERROR(INDEX(B!$N$2:$N$61,MATCH($J27,B!$E$2:$E$61,0))="Sim",FALSE)) | AB27: =IF($J27="",FALSE,LEFT($X27,2)="XX") | AC27: =IF($J27="",FALSE,IFERROR(INDEX(B!$P$2:$P$61,MATCH($J27,B!$E$2:$E$61,0))="Sim",FALSE)) | AE27: =IF(H27="","",HOUR(H27))
A28: =IF(G28="","",IF(G28=G27,"",COUNTIF($G$3:$G$976,G28))) | C28: =IF(G28="","",DAY(G28)) | D28: =IF(G28="","",MONTH(G28)) | E28: =IF(G28="","",YEAR(G28)) | F28: =IF(G28="","",CHOOSE(MONTH(G28),"Janeiro","Fevereiro","Março","Abril","Maio","Junho","Julho","Agosto","Setembro","Outubro","Novembro","Dezembro")) | G28: 46054 | H28: 0.11903935 | I28: https://docs.google.com/spreadsheets/d/1ZiCGoPjLCjuYvujDTXK9Ixbth3tekiLtFBzBrGjPCr4/edit?gid=0#gid=0 | J28: Taxa de Limpeza, Reembolsado ao cliente - [TXLR] | K28: Scout | L28: FALSE | N28: =IF($J28="","",IFERROR(INDEX(B!$F$2:$F$61,MATCH($J28,B!$E$2:$E$61,0))&"","")) | O28: =IF($J28="","",IFERROR(INDEX(B!$G$2:$G$61,MATCH($J28,B!$E$2:$E$61,0))&"","")) | P28: =IF($J28="","",IFERROR(INDEX(B!$H$2:$H$61,MATCH($J28,B!$E$2:$E$61,0))&"","")) | Q28: =IF($J28="","",IFERROR(INDEX(B!$I$2:$I$61,MATCH($J28,B!$E$2:$E$61,0))&"","")) | R28: =IF($J28="","",IFERROR(INDEX(B!$J$2:$J$61,MATCH($J28,B!$E$2:$E$61,0))&"","")) | S28: =IF($J28="","",IFERROR(INDEX(B!$K$2:$K$61,MATCH($J28,B!$E$2:$E$61,0))&"","")) | T28: =IF($J28="","",IFERROR(INDEX(B!$L$2:$L$61,MATCH($J28,B!$E$2:$E$61,0))&"","")) | V28: =IF($J28="","",IFERROR(INDEX(B!$M$2:$M$61,MATCH($J28,B!$E$2:$E$61,0))&"","")) | W28: =IF(I28="","",IFERROR(MID(I28,FIND("/d/",I28)+3,FIND("/edit",I28)-FIND("/d/",I28)-3),I28)) | X28: =IF($J28="","",IFERROR(INDEX(B!$C$2:$C$61,MATCH($J28,B!$E$2:$E$61,0))&"","")) | Z28: =IF($J28="",FALSE,ISNUMBER(SEARCH("scout",$K28))) | AA28: =IF($J28="",FALSE,IFERROR(INDEX(B!$N$2:$N$61,MATCH($J28,B!$E$2:$E$61,0))="Sim",FALSE)) | AB28: =IF($J28="",FALSE,LEFT($X28,2)="XX") | AC28: =IF($J28="",FALSE,IFERROR(INDEX(B!$P$2:$P$61,MATCH($J28,B!$E$2:$E$61,0))="Sim",FALSE)) | AE28: =IF(H28="","",HOUR(H28))
A29: =IF(G29="","",IF(G29=G28,"",COUNTIF($G$3:$G$976,G29))) | C29: =IF(G29="","",DAY(G29)) | D29: =IF(G29="","",MONTH(G29)) | E29: =IF(G29="","",YEAR(G29)) | F29: =IF(G29="","",CHOOSE(MONTH(G29),"Janeiro","Fevereiro","Março","Abril","Maio","Junho","Julho","Agosto","Setembro","Outubro","Novembro","Dezembro")) | G29: 46054 | H29: 0.1334838 | I29: https://docs.google.com/spreadsheets/d/1ZiCGoPjLCjuYvujDTXK9Ixbth3tekiLtFBzBrGjPCr4/edit?gid=0#gid=0 | J29: Comprovante de Pagamento - [CP] | L29: FALSE | N29: =IF($J29="","",IFERROR(INDEX(B!$F$2:$F$61,MATCH($J29,B!$E$2:$E$61,0))&"","")) | O29: =IF($J29="","",IFERROR(INDEX(B!$G$2:$G$61,MATCH($J29,B!$E$2:$E$61,0))&"","")) | P29: =IF($J29="","",IFERROR(INDEX(B!$H$2:$H$61,MATCH($J29,B!$E$2:$E$61,0))&"","")) | Q29: =IF($J29="","",IFERROR(INDEX(B!$I$2:$I$61,MATCH($J29,B!$E$2:$E$61,0))&"","")) | R29: =IF($J29="","",IFERROR(INDEX(B!$J$2:$J$61,MATCH($J29,B!$E$2:$E$61,0))&"","")) | S29: =IF($J29="","",IFERROR(INDEX(B!$K$2:$K$61,MATCH($J29,B!$E$2:$E$61,0))&"","")) | T29: =IF($J29="","",IFERROR(INDEX(B!$L$2:$L$61,MATCH($J29,B!$E$2:$E$61,0))&"","")) | V29: =IF($J29="","",IFERROR(INDEX(B!$M$2:$M$61,MATCH($J29,B!$E$2:$E$61,0))&"","")) | W29: =IF(I29="","",IFERROR(MID(I29,FIND("/d/",I29)+3,FIND("/edit",I29)-FIND("/d/",I29)-3),I29)) | X29: =IF($J29="","",IFERROR(INDEX(B!$C$2:$C$61,MATCH($J29,B!$E$2:$E$61,0))&"","")) | Z29: =IF($J29="",FALSE,ISNUMBER(SEARCH("scout",$K29))) | AA29: =IF($J29="",FALSE,IFERROR(INDEX(B!$N$2:$N$61,MATCH($J29,B!$E$2:$E$61,0))="Sim",FALSE)) | AB29: =IF($J29="",FALSE,LEFT($X29,2)="XX") | AC29: =IF($J29="",FALSE,IFERROR(INDEX(B!$P$2:$P$61,MATCH($J29,B!$E$2:$E$61,0))="Sim",FALSE)) | AE29: =IF(H29="","",HOUR(H29))
A30: =IF(G30="","",IF(G30=G29,"",COUNTIF($G$3:$G$976,G30))) | C30: =IF(G30="","",DAY(G30)) | D30: =IF(G30="","",MONTH(G30)) | E30: =IF(G30="","",YEAR(G30)) | F30: =IF(G30="","",CHOOSE(MONTH(G30),"Janeiro","Fevereiro","Março","Abril","Maio","Junho","Julho","Agosto","Setembro","Outubro","Novembro","Dezembro")) | G30: 46054 | H30: 0.13488426 | I30: https://docs.google.com/spreadsheets/d/1ZiCGoPjLCjuYvujDTXK9Ixbth3tekiLtFBzBrGjPCr4/edit?gid=0#gid=0 | J30: Transferência de LOB (Driver) - [TIDV] | L30: FALSE | N30: =IF($J30="","",IFERROR(INDEX(B!$F$2:$F$61,MATCH($J30,B!$E$2:$E$61,0))&"","")) | O30: =IF($J30="","",IFERROR(INDEX(B!$G$2:$G$61,MATCH($J30,B!$E$2:$E$61,0))&"","")) | P30: =IF($J30="","",IFERROR(INDEX(B!$H$2:$H$61,MATCH($J30,B!$E$2:$E$61,0))&"","")) | Q30: =IF($J30="","",IFERROR(INDEX(B!$I$2:$I$61,MATCH($J30,B!$E$2:$E$61,0))&"","")) | R30: =IF($J30="","",IFERROR(INDEX(B!$J$2:$J$61,MATCH($J30,B!$E$2:$E$61,0))&"","")) | S30: =IF($J30="","",IFERROR(INDEX(B!$K$2:$K$61,MATCH($J30,B!$E$2:$E$61,0))&"","")) | T30: =IF($J30="","",IFERROR(INDEX(B!$L$2:$L$61,MATCH($J30,B!$E$2:$E$61,0))&"","")) | V30: =IF($J30="","",IFERROR(INDEX(B!$M$2:$M$61,MATCH($J30,B!$E$2:$E$61,0))&"","")) | W30: =IF(I30="","",IFERROR(MID(I30,FIND("/d/",I30)+3,FIND("/edit",I30)-FIND("/d/",I30)-3),I30)) | X30: =IF($J30="","",IFERROR(INDEX(B!$C$2:$C$61,MATCH($J30,B!$E$2:$E$61,0))&"","")) | Z30: =IF($J30="",FALSE,ISNUMBER(SEARCH("scout",$K30))) | AA30: =IF($J30="",FALSE,IFERROR(INDEX(B!$N$2:$N$61,MATCH($J30,B!$E$2:$E$61,0))="Sim",FALSE)) | AB30: =IF($J30="",FALSE,LEFT($X30,2)="XX") | AC30: =IF($J30="",FALSE,IFERROR(INDEX(B!$P$2:$P$61,MATCH($J30,B!$E$2:$E$61,0))="Sim",FALSE)) | AE30: =IF(H30="","",HOUR(H30))
A31: =IF(G31="","",IF(G31=G30,"",COUNTIF($G$3:$G$976,G31))) | C31: =IF(G31="","",DAY(G31)) | D31: =IF(G31="","",MONTH(G31)) | E31: =IF(G31="","",YEAR(G31)) | F31: =IF(G31="","",CHOOSE(MONTH(G31),"Janeiro","Fevereiro","Março","Abril","Maio","Junho","Julho","Agosto","Setembro","Outubro","Novembro","Dezembro")) | G31: 46054 | H31: 0.13915509 | I31: https://docs.google.com/spreadsheets/d/1ZiCGoPjLCjuYvujDTXK9Ixbth3tekiLtFBzBrGjPCr4/edit?gid=0#gid=0 | J31: Transferência de LOB (Profissionalismo) - [TIPR] | K31: Scout | L31: FALSE | N31: =IF($J31="","",IFERROR(INDEX(B!$F$2:$F$61,MATCH($J31,B!$E$2:$E$61,0))&"","")) | O31: =IF($J31="","",IFERROR(INDEX(B!$G$2:$G$61,MATCH($J31,B!$E$2:$E$61,0))&"","")) | P31: =IF($J31="","",IFERROR(INDEX(B!$H$2:$H$61,MATCH($J31,B!$E$2:$E$61,0))&"","")) | Q31: =IF($J31="","",IFERROR(INDEX(B!$I$2:$I$61,MATCH($J31,B!$E$2:$E$61,0))&"","")) | R31: =IF($J31="","",IFERROR(INDEX(B!$J$2:$J$61,MATCH($J31,B!$E$2:$E$61,0))&"","")) | S31: =IF($J31="","",IFERROR(INDEX(B!$K$2:$K$61,MATCH($J31,B!$E$2:$E$61,0))&"","")) | T31: =IF($J31="","",IFERROR(INDEX(B!$L$2:$L$61,MATCH($J31,B!$E$2:$E$61,0))&"","")) | V31: =IF($J31="","",IFERROR(INDEX(B!$M$2:$M$61,MATCH($J31,B!$E$2:$E$61,0))&"","")) | W31: =IF(I31="","",IFERROR(MID(I31,FIND("/d/",I31)+3,FIND("/edit",I31)-FIND("/d/",I31)-3),I31)) | X31: =IF($J31="","",IFERROR(INDEX(B!$C$2:$C$61,MATCH($J31,B!$E$2:$E$61,0))&"","")) | Z31: =IF($J31="",FALSE,ISNUMBER(SEARCH("scout",$K31))) | AA31: =IF($J31="",FALSE,IFERROR(INDEX(B!$N$2:$N$61,MATCH($J31,B!$E$2:$E$61,0))="Sim",FALSE)) | AB31: =IF($J31="",FALSE,LEFT($X31,2)="XX") | AC31: =IF($J31="",FALSE,IFERROR(INDEX(B!$P$2:$P$61,MATCH($J31,B!$E$2:$E$61,0))="Sim",FALSE)) | AE31: =IF(H31="","",HOUR(H31))
A32: =IF(G32="","",IF(G32=G31,"",COUNTIF($G$3:$G$976,G32))) | C32: =IF(G32="","",DAY(G32)) | D32: =IF(G32="","",MONTH(G32)) | E32: =IF(G32="","",YEAR(G32)) | F32: =IF(G32="","",CHOOSE(MONTH(G32),"Janeiro","Fevereiro","Março","Abril","Maio","Junho","Julho","Agosto","Setembro","Outubro","Novembro","Dezembro")) | G32: 46054 | H32: 0.14538194 | I32: https://docs.google.com/spreadsheets/d/1ZiCGoPjLCjuYvujDTXK9Ixbth3tekiLtFBzBrGjPCr4/edit?gid=0#gid=0 | J32: Transferência de LOB (Safety) - [TIST] | L32: FALSE | N32: =IF($J32="","",IFERROR(INDEX(B!$F$2:$F$61,MATCH($J32,B!$E$2:$E$61,0))&"","")) | O32: =IF($J32="","",IFERROR(INDEX(B!$G$2:$G$61,MATCH($J32,B!$E$2:$E$61,0))&"","")) | P32: =IF($J32="","",IFERROR(INDEX(B!$H$2:$H$61,MATCH($J32,B!$E$2:$E$61,0))&"","")) | Q32: =IF($J32="","",IFERROR(INDEX(B!$I$2:$I$61,MATCH($J32,B!$E$2:$E$61,0))&"","")) | R32: =IF($J32="","",IFERROR(INDEX(B!$J$2:$J$61,MATCH($J32,B!$E$2:$E$61,0))&"","")) | S32: =IF($J32="","",IFERROR(INDEX(B!$K$2:$K$61,MATCH($J32,B!$E$2:$E$61,0))&"","")) | T32: =IF($J32="","",IFERROR(INDEX(B!$L$2:$L$61,MATCH($J32,B!$E$2:$E$61,0))&"","")) | V32: =IF($J32="","",IFERROR(INDEX(B!$M$2:$M$61,MATCH($J32,B!$E$2:$E$61,0))&"","")) | W32: =IF(I32="","",IFERROR(MID(I32,FIND("/d/",I32)+3,FIND("/edit",I32)-FIND("/d/",I32)-3),I32)) | X32: =IF($J32="","",IFERROR(INDEX(B!$C$2:$C$61,MATCH($J32,B!$E$2:$E$61,0))&"","")) | Z32: =IF($J32="",FALSE,ISNUMBER(SEARCH("scout",$K32))) | AA32: =IF($J32="",FALSE,IFERROR(INDEX(B!$N$2:$N$61,MATCH($J32,B!$E$2:$E$61,0))="Sim",FALSE)) | AB32: =IF($J32="",FALSE,LEFT($X32,2)="XX") | AC32: =IF($J32="",FALSE,IFERROR(INDEX(B!$P$2:$P$61,MATCH($J32,B!$E$2:$E$61,0))="Sim",FALSE)) | AE32: =IF(H32="","",HOUR(H32))
A33: =IF(G33="","",IF(G33=G32,"",COUNTIF($G$3:$G$976,G33))) | C33: =IF(G33="","",DAY(G33)) | D33: =IF(G33="","",MONTH(G33)) | E33: =IF(G33="","",YEAR(G33)) | F33: =IF(G33="","",CHOOSE(MONTH(G33),"Janeiro","Fevereiro","Março","Abril","Maio","Junho","Julho","Agosto","Setembro","Outubro","Novembro","Dezembro")) | G33: 46054 | H33: 0.14726852 | I33: https://docs.google.com/spreadsheets/d/1ZiCGoPjLCjuYvujDTXK9Ixbth3tekiLtFBzBrGjPCr4/edit?gid=0#gid=0 | J33: Overpaid, Excede o limite, Sem comprovante - [OPEN] | K33: Scout | L33: FALSE | N33: =IF($J33="","",IFERROR(INDEX(B!$F$2:$F$61,MATCH($J33,B!$E$2:$E$61,0))&"","")) | O33: =IF($J33="","",IFERROR(INDEX(B!$G$2:$G$61,MATCH($J33,B!$E$2:$E$61,0))&"","")) | P33: =IF($J33="","",IFERROR(INDEX(B!$H$2:$H$61,MATCH($J33,B!$E$2:$E$61,0))&"","")) | Q33: =IF($J33="","",IFERROR(INDEX(B!$I$2:$I$61,MATCH($J33,B!$E$2:$E$61,0))&"","")) | R33: =IF($J33="","",IFERROR(INDEX(B!$J$2:$J$61,MATCH($J33,B!$E$2:$E$61,0))&"","")) | S33: =IF($J33="","",IFERROR(INDEX(B!$K$2:$K$61,MATCH($J33,B!$E$2:$E$61,0))&"","")) | T33: =IF($J33="","",IFERROR(INDEX(B!$L$2:$L$61,MATCH($J33,B!$E$2:$E$61,0))&"","")) | V33: =IF($J33="","",IFERROR(INDEX(B!$M$2:$M$61,MATCH($J33,B!$E$2:$E$61,0))&"","")) | W33: =IF(I33="","",IFERROR(MID(I33,FIND("/d/",I33)+3,FIND("/edit",I33)-FIND("/d/",I33)-3),I33)) | X33: =IF($J33="","",IFERROR(INDEX(B!$C$2:$C$61,MATCH($J33,B!$E$2:$E$61,0))&"","")) | Z33: =IF($J33="",FALSE,ISNUMBER(SEARCH("scout",$K33))) | AA33: =IF($J33="",FALSE,IFERROR(INDEX(B!$N$2:$N$61,MATCH($J33,B!$E$2:$E$61,0))="Sim",FALSE)) | AB33: =IF($J33="",FALSE,LEFT($X33,2)="XX") | AC33: =IF($J33="",FALSE,IFERROR(INDEX(B!$P$2:$P$61,MATCH($J33,B!$E$2:$E$61,0))="Sim",FALSE)) | AE33: =IF(H33="","",HOUR(H33))
A34: =IF(G34="","",IF(G34=G33,"",COUNTIF($G$3:$G$976,G34))) | C34: =IF(G34="","",DAY(G34)) | D34: =IF(G34="","",MONTH(G34)) | E34: =IF(G34="","",YEAR(G34)) | F34: =IF(G34="","",CHOOSE(MONTH(G34),"Janeiro","Fevereiro","Março","Abril","Maio","Junho","Julho","Agosto","Setembro","Outubro","Novembro","Dezembro")) | G34: 46054 | H34: 0.1519213 | I34: https://docs.google.com/spreadsheets/d/1ZiCGoPjLCjuYvujDTXK9Ixbth3tekiLtFBzBrGjPCr4/edit?gid=0#gid=0 | J34: Comprovante de Pagamento - [CP] | K34: Scout | L34: FALSE | N34: =IF($J34="","",IFERROR(INDEX(B!$F$2:$F$61,MATCH($J34,B!$E$2:$E$61,0))&"","")) | O34: =IF($J34="","",IFERROR(INDEX(B!$G$2:$G$61,MATCH($J34,B!$E$2:$E$61,0))&"","")) | P34: =IF($J34="","",IFERROR(INDEX(B!$H$2:$H$61,MATCH($J34,B!$E$2:$E$61,0))&"","")) | Q34: =IF($J34="","",IFERROR(INDEX(B!$I$2:$I$61,MATCH($J34,B!$E$2:$E$61,0))&"","")) | R34: =IF($J34="","",IFERROR(INDEX(B!$J$2:$J$61,MATCH($J34,B!$E$2:$E$61,0))&"","")) | S34: =IF($J34="","",IFERROR(INDEX(B!$K$2:$K$61,MATCH($J34,B!$E$2:$E$61,0))&"","")) | T34: =IF($J34="","",IFERROR(INDEX(B!$L$2:$L$61,MATCH($J34,B!$E$2:$E$61,0))&"","")) | V34: =IF($J34="","",IFERROR(INDEX(B!$M$2:$M$61,MATCH($J34,B!$E$2:$E$61,0))&"","")) | W34: =IF(I34="","",IFERROR(MID(I34,FIND("/d/",I34)+3,FIND("/edit",I34)-FIND("/d/",I34)-3),I34)) | X34: =IF($J34="","",IFERROR(INDEX(B!$C$2:$C$61,MATCH($J34,B!$E$2:$E$61,0))&"","")) | Z34: =IF($J34="",FALSE,ISNUMBER(SEARCH("scout",$K34))) | AA34: =IF($J34="",FALSE,IFERROR(INDEX(B!$N$2:$N$61,MATCH($J34,B!$E$2:$E$61,0))="Sim",FALSE)) | AB34: =IF($J34="",FALSE,LEFT($X34,2)="XX") | AC34: =IF($J34="",FALSE,IFERROR(INDEX(B!$P$2:$P$61,MATCH($J34,B!$E$2:$E$61,0))="Sim",FALSE)) | AE34: =IF(H34="","",HOUR(H34))
A35: =IF(G35="","",IF(G35=G34,"",COUNTIF($G$3:$G$976,G35))) | C35: =IF(G35="","",DAY(G35)) | D35: =IF(G35="","",MONTH(G35)) | E35: =IF(G35="","",YEAR(G35)) | F35: =IF(G35="","",CHOOSE(MONTH(G35),"Janeiro","Fevereiro","Março","Abril","Maio","Junho","Julho","Agosto","Setembro","Outubro","Novembro","Dezembro")) | G35: 46054 | H35: 0.15673611 | I35: https://docs.google.com/spreadsheets/d/1ZiCGoPjLCjuYvujDTXK9Ixbth3tekiLtFBzBrGjPCr4/edit?gid=0#gid=0 | J35: Pushback (Agradecimento) - [XXA] | L35: FALSE | N35: =IF($J35="","",IFERROR(INDEX(B!$F$2:$F$61,MATCH($J35,B!$E$2:$E$61,0))&"","")) | O35: =IF($J35="","",IFERROR(INDEX(B!$G$2:$G$61,MATCH($J35,B!$E$2:$E$61,0))&"","")) | P35: =IF($J35="","",IFERROR(INDEX(B!$H$2:$H$61,MATCH($J35,B!$E$2:$E$61,0))&"","")) | Q35: =IF($J35="","",IFERROR(INDEX(B!$I$2:$I$61,MATCH($J35,B!$E$2:$E$61,0))&"","")) | R35: =IF($J35="","",IFERROR(INDEX(B!$J$2:$J$61,MATCH($J35,B!$E$2:$E$61,0))&"","")) | S35: =IF($J35="","",IFERROR(INDEX(B!$K$2:$K$61,MATCH($J35,B!$E$2:$E$61,0))&"","")) | T35: =IF($J35="","",IFERROR(INDEX(B!$L$2:$L$61,MATCH($J35,B!$E$2:$E$61,0))&"","")) | V35: =IF($J35="","",IFERROR(INDEX(B!$M$2:$M$61,MATCH($J35,B!$E$2:$E$61,0))&"","")) | W35: =IF(I35="","",IFERROR(MID(I35,FIND("/d/",I35)+3,FIND("/edit",I35)-FIND("/d/",I35)-3),I35)) | X35: =IF($J35="","",IFERROR(INDEX(B!$C$2:$C$61,MATCH($J35,B!$E$2:$E$61,0))&"","")) | Z35: =IF($J35="",FALSE,ISNUMBER(SEARCH("scout",$K35))) | AA35: =IF($J35="",FALSE,IFERROR(INDEX(B!$N$2:$N$61,MATCH($J35,B!$E$2:$E$61,0))="Sim",FALSE)) | AB35: =IF($J35="",FALSE,LEFT($X35,2)="XX") | AC35: =IF($J35="",FALSE,IFERROR(INDEX(B!$P$2:$P$61,MATCH($J35,B!$E$2:$E$61,0))="Sim",FALSE)) | AE35: =IF(H35="","",HOUR(H35))
A36: =IF(G36="","",IF(G36=G35,"",COUNTIF($G$3:$G$976,G36))) | C36: =IF(G36="","",DAY(G36)) | D36: =IF(G36="","",MONTH(G36)) | E36: =IF(G36="","",YEAR(G36)) | F36: =IF(G36="","",CHOOSE(MONTH(G36),"Janeiro","Fevereiro","Março","Abril","Maio","Junho","Julho","Agosto","Setembro","Outubro","Novembro","Dezembro")) | G36: 46054 | H36: 0.15689815 | I36: https://docs.google.com/spreadsheets/d/1ZiCGoPjLCjuYvujDTXK9Ixbth3tekiLtFBzBrGjPCr4/edit?gid=0#gid=0 | J36: Mais informações Gerais - [AA] | K36: Scout | L36: FALSE | N36: =IF($J36="","",IFERROR(INDEX(B!$F$2:$F$61,MATCH($J36,B!$E$2:$E$61,0))&"","")) | O36: =IF($J36="","",IFERROR(INDEX(B!$G$2:$G$61,MATCH($J36,B!$E$2:$E$61,0))&"","")) | P36: =IF($J36="","",IFERROR(INDEX(B!$H$2:$H$61,MATCH($J36,B!$E$2:$E$61,0))&"","")) | Q36: =IF($J36="","",IFERROR(INDEX(B!$I$2:$I$61,MATCH($J36,B!$E$2:$E$61,0))&"","")) | R36: =IF($J36="","",IFERROR(INDEX(B!$J$2:$J$61,MATCH($J36,B!$E$2:$E$61,0))&"","")) | S36: =IF($J36="","",IFERROR(INDEX(B!$K$2:$K$61,MATCH($J36,B!$E$2:$E$61,0))&"","")) | T36: =IF($J36="","",IFERROR(INDEX(B!$L$2:$L$61,MATCH($J36,B!$E$2:$E$61,0))&"","")) | V36: =IF($J36="","",IFERROR(INDEX(B!$M$2:$M$61,MATCH($J36,B!$E$2:$E$61,0))&"","")) | W36: =IF(I36="","",IFERROR(MID(I36,FIND("/d/",I36)+3,FIND("/edit",I36)-FIND("/d/",I36)-3),I36)) | X36: =IF($J36="","",IFERROR(INDEX(B!$C$2:$C$61,MATCH($J36,B!$E$2:$E$61,0))&"","")) | Z36: =IF($J36="",FALSE,ISNUMBER(SEARCH("scout",$K36))) | AA36: =IF($J36="",FALSE,IFERROR(INDEX(B!$N$2:$N$61,MATCH($J36,B!$E$2:$E$61,0))="Sim",FALSE)) | AB36: =IF($J36="",FALSE,LEFT($X36,2)="XX") | AC36: =IF($J36="",FALSE,IFERROR(INDEX(B!$P$2:$P$61,MATCH($J36,B!$E$2:$E$61,0))="Sim",FALSE)) | AE36: =IF(H36="","",HOUR(H36))
A37: =IF(G37="","",IF(G37=G36,"",COUNTIF($G$3:$G$976,G37))) | C37: =IF(G37="","",DAY(G37)) | D37: =IF(G37="","",MONTH(G37)) | E37: =IF(G37="","",YEAR(G37)) | F37: =IF(G37="","",CHOOSE(MONTH(G37),"Janeiro","Fevereiro","Março","Abril","Maio","Junho","Julho","Agosto","Setembro","Outubro","Novembro","Dezembro")) | G37: 46054 | H37: 0.16673611 | I37: https://docs.google.com/spreadsheets/d/1ZiCGoPjLCjuYvujDTXK9Ixbth3tekiLtFBzBrGjPCr4/edit?gid=0#gid=0 | J37: Transferência de LOB (Lost Items) - [TILI] | L37: FALSE | N37: =IF($J37="","",IFERROR(INDEX(B!$F$2:$F$61,MATCH($J37,B!$E$2:$E$61,0))&"","")) | O37: =IF($J37="","",IFERROR(INDEX(B!$G$2:$G$61,MATCH($J37,B!$E$2:$E$61,0))&"","")) | P37: =IF($J37="","",IFERROR(INDEX(B!$H$2:$H$61,MATCH($J37,B!$E$2:$E$61,0))&"","")) | Q37: =IF($J37="","",IFERROR(INDEX(B!$I$2:$I$61,MATCH($J37,B!$E$2:$E$61,0))&"","")) | R37: =IF($J37="","",IFERROR(INDEX(B!$J$2:$J$61,MATCH($J37,B!$E$2:$E$61,0))&"","")) | S37: =IF($J37="","",IFERROR(INDEX(B!$K$2:$K$61,MATCH($J37,B!$E$2:$E$61,0))&"","")) | T37: =IF($J37="","",IFERROR(INDEX(B!$L$2:$L$61,MATCH($J37,B!$E$2:$E$61,0))&"","")) | V37: =IF($J37="","",IFERROR(INDEX(B!$M$2:$M$61,MATCH($J37,B!$E$2:$E$61,0))&"","")) | W37: =IF(I37="","",IFERROR(MID(I37,FIND("/d/",I37)+3,FIND("/edit",I37)-FIND("/d/",I37)-3),I37)) | X37: =IF($J37="","",IFERROR(INDEX(B!$C$2:$C$61,MATCH($J37,B!$E$2:$E$61,0))&"","")) | Z37: =IF($J37="",FALSE,ISNUMBER(SEARCH("scout",$K37))) | AA37: =IF($J37="",FALSE,IFERROR(INDEX(B!$N$2:$N$61,MATCH($J37,B!$E$2:$E$61,0))="Sim",FALSE)) | AB37: =IF($J37="",FALSE,LEFT($X37,2)="XX") | AC37: =IF($J37="",FALSE,IFERROR(INDEX(B!$P$2:$P$61,MATCH($J37,B!$E$2:$E$61,0))="Sim",FALSE)) | AE37: =IF(H37="","",HOUR(H37))
